Workbook
Name tab: [1]info!$B$9

Sheet Peso Fardos
I2: CONSUMO MATÉRIA PRIMA SAPIENS | L2: SAIDA DA EMPRESA | O2: FATURADO | R2: NECESSIDADE MATÉRIA PRIMA A PRODUZIR
A3: CÓDIGO | B3: DESCRIÇÃO | C3: QUANT. DO FARDO | D3: PESO PACOTE | E3: PESO PACOTE | F3: PESO DO FARDO | G3: PESO DO FARDO | I3: PRODUÇÃO FARDOS | J3: PRODUÇÃO EM KILOS | L3: SAIDA FARDOS | M3: SAIDA EM KILOS | O3: SAIDA FARDOS | P3: SAIDA EM KILOS | R3: ENTRADA FARDOS | S3: ENTRADA EM KILOS
A4: 011 | B4: FLOCADO NUTRIVITA 12 X 500 | C4: 12 | D4: 0.5 | E4: 0.505 | F4: =C4*D4 -> 6 | G4: =C4*E4 -> 6.06 | I4: =IF(ISBLANK($A$2),SUMIFS(Entradas!C:C,Entradas!A:A,'Cadastro-Estoque'!A:A),SUMIFS(Entradas!C:C,Entradas!A:A,'Cadastro-Estoque'!A:A,Entradas!B:B,CONCATENATE("<=",$A$2))) -> 0 | J4: =I4*G4 -> 0 | L4: =IF(ISBLANK($A$2),SUMIFS(Saidas!C:C,Saidas!A:A,'Cadastro-Estoque'!A:A),SUMIFS(Saidas!C:C,Saidas!A:A,'Cadastro-Estoque'!A:A,Saidas!B:B,CONCATENATE("<=",$A$2))) -> 0 | M4: =L4*F4 -> 0 | O4: =IF(ISBLANK($A$2),SUMIFS(Faturado!C:C,Faturado!A:A,'Cadastro-Estoque'!A:A),SUMIFS(Faturado!C:C,Faturado!A:A,'Cadastro-Estoque'!A:A,Faturado!B:B,CONCATENATE("<=",$A$2))) -> 0 | P4: =O4*F4 -> 0 | R4: =IF(ISBLANK($A$2),SUMIFS('PRODUTOS A PRODUZIR'!C:C,'PRODUTOS A PRODUZIR'!A:A,'Cadastro-Estoque'!A:A),SUMIFS('PRODUTOS A PRODUZIR'!C:C,'PRODUTOS A PRODUZIR'!A:A,'Cadastro-Estoque'!A:A,'PRODUTOS A PRODUZIR'!B:B,CONCATENATE("<=",$A$2))) -> 0 | S4: =R4*F4 -> 0
A5: 011 | B5: FLOCADO NUTRIVITA 30 X 500 | C5: 30 | D5: 0.5 | E5: 0.505 | F5: =C5*D5 -> 15 | G5: =C5*E5 -> 15.15 | I5: =IF(ISBLANK($A$2),SUMIFS(Entradas!C:C,Entradas!A:A,'Cadastro-Estoque'!A:A),SUMIFS(Entradas!C:C,Entradas!A:A,'Cadastro-Estoque'!A:A,Entradas!B:B,CONCATENATE("<=",$A$2))) -> 1486 | J5: =I5*G5 -> 22512.9 | L5: =IF(ISBLANK($A$2),SUMIFS(Saidas!C:C,Saidas!A:A,'Cadastro-Estoque'!A:A),SUMIFS(Saidas!C:C,Saidas!A:A,'Cadastro-Estoque'!A:A,Saidas!B:B,CONCATENATE("<=",$A$2))) -> 4875 | M5: =L5*F5 -> 73125 | O5: =IF(ISBLANK($A$2),SUMIFS(Faturado!C:C,Faturado!A:A,'Cadastro-Estoque'!A:A),SUMIFS(Faturado!C:C,Faturado!A:A,'Cadastro-Estoque'!A:A,Faturado!B:B,CONCATENATE("<=",$A$2))) -> 0 | P5: =O5*F5 -> 0 | R5: =IF(ISBLANK($A$2),SUMIFS('PRODUTOS A PRODUZIR'!C:C,'PRODUTOS A PRODUZIR'!A:A,'Cadastro-Estoque'!A:A),SUMIFS('PRODUTOS A PRODUZIR'!C:C,'PRODUTOS A PRODUZIR'!A:A,'Cadastro-Estoque'!A:A,'PRODUTOS A PRODUZIR'!B:B,CONCATENATE("<=",$A$2))) -> 0 | S5: =R5*F5 -> 0
A6: 012 | B6: FLOCADO VITABEM 30 X 500 | C6: 30 | D6: 0.5 | E6: 0.505 | F6: =C6*D6 -> 15 | G6: =C6*E6 -> 15.15 | I6: =IF(ISBLANK($A$2),SUMIFS(Entradas!C:C,Entradas!A:A,'Cadastro-Estoque'!A:A),SUMIFS(Entradas!C:C,Entradas!A:A,'Cadastro-Estoque'!A:A,Entradas!B:B,CONCATENATE("<=",$A$2))) -> 0 | J6: =I6*G6 -> 0 | L6: =IF(ISBLANK($A$2),SUMIFS(Saidas!C:C,Saidas!A:A,'Cadastro-Estoque'!A:A),SUMIFS(Saidas!C:C,Saidas!A:A,'Cadastro-Estoque'!A:A,Saidas!B:B,CONCATENATE("<=",$A$2))) -> 0 | M6: =L6*F6 -> 0 | O6: =IF(ISBLANK($A$2),SUMIFS(Faturado!C:C,Faturado!A:A,'Cadastro-Estoque'!A:A),SUMIFS(Faturado!C:C,Faturado!A:A,'Cadastro-Estoque'!A:A,Faturado!B:B,CONCATENATE("<=",$A$2))) -> 0 | P6: =O6*F6 -> 0 | R6: =IF(ISBLANK($A$2),SUMIFS('PRODUTOS A PRODUZIR'!C:C,'PRODUTOS A PRODUZIR'!A:A,'Cadastro-Estoque'!A:A),SUMIFS('PRODUTOS A PRODUZIR'!C:C,'PRODUTOS A PRODUZIR'!A:A,'Cadastro-Estoque'!A:A,'PRODUTOS A PRODUZIR'!B:B,CONCATENATE("<=",$A$2))) -> 0 | S6: =R6*F6 -> 0
A7: 016 | B7: FLOCADO VITABRAS 30 X 400 | C7: 30 | D7: 0.5 | E7: 0.505 | F7: 12 | G7: 12.15 | I7: =IF(ISBLANK($A$2),SUMIFS(Entradas!C:C,Entradas!A:A,'Cadastro-Estoque'!A:A),SUMIFS(Entradas!C:C,Entradas!A:A,'Cadastro-Estoque'!A:A,Entradas!B:B,CONCATENATE("<=",$A$2))) -> 0 | J7: =I7*G7 -> 0 | L7: =IF(ISBLANK($A$2),SUMIFS(Saidas!C:C,Saidas!A:A,'Cadastro-Estoque'!A:A),SUMIFS(Saidas!C:C,Saidas!A:A,'Cadastro-Estoque'!A:A,Saidas!B:B,CONCATENATE("<=",$A$2))) -> 0 | M7: =L7*F7 -> 0 | O7: =IF(ISBLANK($A$2),SUMIFS(Faturado!C:C,Faturado!A:A,'Cadastro-Estoque'!A:A),SUMIFS(Faturado!C:C,Faturado!A:A,'Cadastro-Estoque'!A:A,Faturado!B:B,CONCATENATE("<=",$A$2))) -> 0 | P7: =O7*F7 -> 0 | R7: =IF(ISBLANK($A$2),SUMIFS('PRODUTOS A PRODUZIR'!C:C,'PRODUTOS A PRODUZIR'!A:A,'Cadastro-Estoque'!A:A),SUMIFS('PRODUTOS A PRODUZIR'!C:C,'PRODUTOS A PRODUZIR'!A:A,'Cadastro-Estoque'!A:A,'PRODUTOS A PRODUZIR'!B:B,CONCATENATE("<=",$A$2))) -> 0 | S7: =R7*F7 -> 0
A8: 022 | B8: FLOCADO VITABRASIL 30 X 500 | C8: 30 | D8: 0.4 | E8: 0.405 | F8: 15 | G8: 15.15 | I8: =IF(ISBLANK($A$2),SUMIFS(Entradas!C:C,Entradas!A:A,'Cadastro-Estoque'!A:A),SUMIFS(Entradas!C:C,Entradas!A:A,'Cadastro-Estoque'!A:A,Entradas!B:B,CONCATENATE("<=",$A$2))) -> 0 | J8: =I8*G8 -> 0 | L8: =IF(ISBLANK($A$2),SUMIFS(Saidas!C:C,Saidas!A:A,'Cadastro-Estoque'!A:A),SUMIFS(Saidas!C:C,Saidas!A:A,'Cadastro-Estoque'!A:A,Saidas!B:B,CONCATENATE("<=",$A$2))) -> 0 | M8: =L8*F8 -> 0 | O8: =IF(ISBLANK($A$2),SUMIFS(Faturado!C:C,Faturado!A:A,'Cadastro-Estoque'!A:A),SUMIFS(Faturado!C:C,Faturado!A:A,'Cadastro-Estoque'!A:A,Faturado!B:B,CONCATENATE("<=",$A$2))) -> 0 | P8: =O8*F8 -> 0 | R8: =IF(ISBLANK($A$2),SUMIFS('PRODUTOS A PRODUZIR'!C:C,'PRODUTOS A PRODUZIR'!A:A,'Cadastro-Estoque'!A:A),SUMIFS('PRODUTOS A PRODUZIR'!C:C,'PRODUTOS A PRODUZIR'!A:A,'Cadastro-Estoque'!A:A,'PRODUTOS A PRODUZIR'!B:B,CONCATENATE("<=",$A$2))) -> 0 | S8: =R8*F8 -> 0
A9: 019 | B9: FLOCADO PURO MILHO 12 X 500 | C9: 12 | D9: 0.5 | E9: 0.505 | F9: =C9*D9 -> 6 | G9: =C9*E9 -> 6.06 | I9: =IF(ISBLANK($A$2),SUMIFS(Entradas!C:C,Entradas!A:A,'Cadastro-Estoque'!A:A),SUMIFS(Entradas!C:C,Entradas!A:A,'Cadastro-Estoque'!A:A,Entradas!B:B,CONCATENATE("<=",$A$2))) -> 0 | J9: =I9*G9 -> 0 | L9: =IF(ISBLANK($A$2),SUMIFS(Saidas!C:C,Saidas!A:A,'Cadastro-Estoque'!A:A),SUMIFS(Saidas!C:C,Saidas!A:A,'Cadastro-Estoque'!A:A,Saidas!B:B,CONCATENATE("<=",$A$2))) -> 0 | M9: =L9*F9 -> 0 | O9: =IF(ISBLANK($A$2),SUMIFS(Faturado!C:C,Faturado!A:A,'Cadastro-Estoque'!A:A),SUMIFS(Faturado!C:C,Faturado!A:A,'Cadastro-Estoque'!A:A,Faturado!B:B,CONCATENATE("<=",$A$2))) -> 0 | P9: =O9*F9 -> 0 | R9: =IF(ISBLANK($A$2),SUMIFS('PRODUTOS A PRODUZIR'!C:C,'PRODUTOS A PRODUZIR'!A:A,'Cadastro-Estoque'!A:A),SUMIFS('PRODUTOS A PRODUZIR'!C:C,'PRODUTOS A PRODUZIR'!A:A,'Cadastro-Estoque'!A:A,'PRODUTOS A PRODUZIR'!B:B,CONCATENATE("<=",$A$2))) -> 0 | S9: =R9*F9 -> 0
A10: 019 | B10: FLOCADO PURO MILHO 30 X 500 | C10: 30 | D10: 0.5 | E10: 0.505 | F10: =C10*D10 -> 15 | G10: =C10*E10 -> 15.15 | I10: =IF(ISBLANK($A$2),SUMIFS(Entradas!C:C,Entradas!A:A,'Cadastro-Estoque'!A:A),SUMIFS(Entradas!C:C,Entradas!A:A,'Cadastro-Estoque'!A:A,Entradas!B:B,CONCATENATE("<=",$A$2))) -> 0 | J10: =I10*G10 -> 0 | L10: =IF(ISBLANK($A$2),SUMIFS(Saidas!C:C,Saidas!A:A,'Cadastro-Estoque'!A:A),SUMIFS(Saidas!C:C,Saidas!A:A,'Cadastro-Estoque'!A:A,Saidas!B:B,CONCATENATE("<=",$A$2))) -> 0 | M10: =L10*F10 -> 0 | O10: =IF(ISBLANK($A$2),SUMIFS(Faturado!C:C,Faturado!A:A,'Cadastro-Estoque'!A:A),SUMIFS(Faturado!C:C,Faturado!A:A,'Cadastro-Estoque'!A:A,Faturado!B:B,CONCATENATE("<=",$A$2))) -> 0 | P10: =O10*F10 -> 0 | R10: =IF(ISBLANK($A$2),SUMIFS('PRODUTOS A PRODUZIR'!C:C,'PRODUTOS A PRODUZIR'!A:A,'Cadastro-Estoque'!A:A),SUMIFS('PRODUTOS A PRODUZIR'!C:C,'PRODUTOS A PRODUZIR'!A:A,'Cadastro-Estoque'!A:A,'PRODUTOS A PRODUZIR'!B:B,CONCATENATE("<=",$A$2))) -> 0 | S10: =R10*F10 -> 0
A11: 050 | B11: FLOCADO CORDEIRO 30 X 500 | C11: 30 | D11: 0.5 | E11: 0.505 | F11: =C11*D11 -> 15 | G11: =C11*E11 -> 15.15 | I11: =IF(ISBLANK($A$2),SUMIFS(Entradas!C:C,Entradas!A:A,'Cadastro-Estoque'!A:A),SUMIFS(Entradas!C:C,Entradas!A:A,'Cadastro-Estoque'!A:A,Entradas!B:B,CONCATENATE("<=",$A$2))) -> 0 | J11: =I11*G11 -> 0 | L11: =IF(ISBLANK($A$2),SUMIFS(Saidas!C:C,Saidas!A:A,'Cadastro-Estoque'!A:A),SUMIFS(Saidas!C:C,Saidas!A:A,'Cadastro-Estoque'!A:A,Saidas!B:B,CONCATENATE("<=",$A$2))) -> 0 | M11: =L11*F11 -> 0 | O11: =IF(ISBLANK($A$2),SUMIFS(Faturado!C:C,Faturado!A:A,'Cadastro-Estoque'!A:A),SUMIFS(Faturado!C:C,Faturado!A:A,'Cadastro-Estoque'!A:A,Faturado!B:B,CONCATENATE("<=",$A$2))) -> 0 | P11: =O11*F11 -> 0 | R11: =IF(ISBLANK($A$2),SUMIFS('PRODUTOS A PRODUZIR'!C:C,'PRODUTOS A PRODUZIR'!A:A,'Cadastro-Estoque'!A:A),SUMIFS('PRODUTOS A PRODUZIR'!C:C,'PRODUTOS A PRODUZIR'!A:A,'Cadastro-Estoque'!A:A,'PRODUTOS A PRODUZIR'!B:B,CONCATENATE("<=",$A$2))) -> 0 | S11: =R11*F11 -> 0
A12: 094 | B12: FLOCADO M & K 12 X 500 | C12: 12 | D12: 0.5 | E12: 0.505 | F12: =C12*D12 -> 6 | G12: =C12*E12 -> 6.06 | I12: =IF(ISBLANK($A$2),SUMIFS(Entradas!C:C,Entradas!A:A,'Cadastro-Estoque'!A:A),SUMIFS(Entradas!C:C,Entradas!A:A,'Cadastro-Estoque'!A:A,Entradas!B:B,CONCATENATE("<=",$A$2))) -> 0 | J12: =I12*G12 -> 0 | L12: =IF(ISBLANK($A$2),SUMIFS(Saidas!C:C,Saidas!A:A,'Cadastro-Estoque'!A:A),SUMIFS(Saidas!C:C,Saidas!A:A,'Cadastro-Estoque'!A:A,Saidas!B:B,CONCATENATE("<=",$A$2))) -> 0 | M12: =L12*F12 -> 0 | O12: =IF(ISBLANK($A$2),SUMIFS(Faturado!C:C,Faturado!A:A,'Cadastro-Estoque'!A:A),SUMIFS(Faturado!C:C,Faturado!A:A,'Cadastro-Estoque'!A:A,Faturado!B:B,CONCATENATE("<=",$A$2))) -> 0 | P12: =O12*F12 -> 0 | R12: =IF(ISBLANK($A$2),SUMIFS('PRODUTOS A PRODUZIR'!C:C,'PRODUTOS A PRODUZIR'!A:A,'Cadastro-Estoque'!A:A),SUMIFS('PRODUTOS A PRODUZIR'!C:C,'PRODUTOS A PRODUZIR'!A:A,'Cadastro-Estoque'!A:A,'PRODUTOS A PRODUZIR'!B:B,CONCATENATE("<=",$A$2))) -> 0 | S12: =R12*F12 -> 0
F13: =C13*D13 -> 0 | G13: =C13*E13 -> 0 | I13: =IF(ISBLANK($A$2),SUMIFS(Entradas!C:C,Entradas!A:A,'Cadastro-Estoque'!A:A),SUMIFS(Entradas!C:C,Entradas!A:A,'Cadastro-Estoque'!A:A,Entradas!B:B,CONCATENATE("<=",$A$2))) -> 0 | J13: =I13*G13 -> 0 | L13: =IF(ISBLANK($A$2),SUMIFS(Saidas!C:C,Saidas!A:A,'Cadastro-Estoque'!A:A),SUMIFS(Saidas!C:C,Saidas!A:A,'Cadastro-Estoque'!A:A,Saidas!B:B,CONCATENATE("<=",$A$2))) -> 0 | M13: =L13*F13 -> 0 | O13: =IF(ISBLANK($A$2),SUMIFS(Faturado!C:C,Faturado!A:A,'Cadastro-Estoque'!A:A),SUMIFS(Faturado!C:C,Faturado!A:A,'Cadastro-Estoque'!A:A,Faturado!B:B,CONCATENATE("<=",$A$2))) -> 0 | P13: =O13*F13 -> 0 | R13: =IF(ISBLANK($A$2),SUMIFS('PRODUTOS A PRODUZIR'!C:C,'PRODUTOS A PRODUZIR'!A:A,'Cadastro-Estoque'!A:A),SUMIFS('PRODUTOS A PRODUZIR'!C:C,'PRODUTOS A PRODUZIR'!A:A,'Cadastro-Estoque'!A:A,'PRODUTOS A PRODUZIR'!B:B,CONCATENATE("<=",$A$2))) -> 0 | S13: =R13*F13 -> 0
A14: 036 | B14: POLENTA KISABOR 30 X 500 | C14: 30 | D14: 0.5 | E14: 0.505 | F14: =C14*D14 -> 15 | G14: =C14*E14 -> 15.15 | I14: =IF(ISBLANK($A$2),SUMIFS(Entradas!C:C,Entradas!A:A,'Cadastro-Estoque'!A:A),SUMIFS(Entradas!C:C,Entradas!A:A,'Cadastro-Estoque'!A:A,Entradas!B:B,CONCATENATE("<=",$A$2))) -> 0 | J14: =I14*G14 -> 0 | L14: =IF(ISBLANK($A$2),SUMIFS(Saidas!C:C,Saidas!A:A,'Cadastro-Estoque'!A:A),SUMIFS(Saidas!C:C,Saidas!A:A,'Cadastro-Estoque'!A:A,Saidas!B:B,CONCATENATE("<=",$A$2))) -> 0 | M14: =L14*F14 -> 0 | O14: =IF(ISBLANK($A$2),SUMIFS(Faturado!C:C,Faturado!A:A,'Cadastro-Estoque'!A:A),SUMIFS(Faturado!C:C,Faturado!A:A,'Cadastro-Estoque'!A:A,Faturado!B:B,CONCATENATE("<=",$A$2))) -> 0 | P14: =O14*F14 -> 0 | R14: =IF(ISBLANK($A$2),SUMIFS('PRODUTOS A PRODUZIR'!C:C,'PRODUTOS A PRODUZIR'!A:A,'Cadastro-Estoque'!A:A),SUMIFS('PRODUTOS A PRODUZIR'!C:C,'PRODUTOS A PRODUZIR'!A:A,'Cadastro-Estoque'!A:A,'PRODUTOS A PRODUZIR'!B:B,CONCATENATE("<=",$A$2))) -> 0 | S14: =R14*F14 -> 0
A15: 036 | B15: POLENTA KISABOR 12 X 500 | C15: 12 | D15: 0.5 | E15: 0.505 | F15: =C15*D15 -> 6 | G15: =C15*E15 -> 6.06 | I15: =IF(ISBLANK($A$2),SUMIFS(Entradas!C:C,Entradas!A:A,'Cadastro-Estoque'!A:A),SUMIFS(Entradas!C:C,Entradas!A:A,'Cadastro-Estoque'!A:A,Entradas!B:B,CONCATENATE("<=",$A$2))) -> 0 | J15: =I15*G15 -> 0 | L15: =IF(ISBLANK($A$2),SUMIFS(Saidas!C:C,Saidas!A:A,'Cadastro-Estoque'!A:A),SUMIFS(Saidas!C:C,Saidas!A:A,'Cadastro-Estoque'!A:A,Saidas!B:B,CONCATENATE("<=",$A$2))) -> 0 | M15: =L15*F15 -> 0 | O15: =IF(ISBLANK($A$2),SUMIFS(Faturado!C:C,Faturado!A:A,'Cadastro-Estoque'!A:A),SUMIFS(Faturado!C:C,Faturado!A:A,'Cadastro-Estoque'!A:A,Faturado!B:B,CONCATENATE("<=",$A$2))) -> 0 | P15: =O15*F15 -> 0 | R15: =IF(ISBLANK($A$2),SUMIFS('PRODUTOS A PRODUZIR'!C:C,'PRODUTOS A PRODUZIR'!A:A,'Cadastro-Estoque'!A:A),SUMIFS('PRODUTOS A PRODUZIR'!C:C,'PRODUTOS A PRODUZIR'!A:A,'Cadastro-Estoque'!A:A,'PRODUTOS A PRODUZIR'!B:B,CONCATENATE("<=",$A$2))) -> 0 | S15: =R15*F15 -> 0
A16: 037 | B16: POLENTA NUTRIVITA 30 X 500 | C16: 30 | D16: 0.5 | E16: 0.505 | F16: =C16*D16 -> 15 | G16: =C16*E16 -> 15.15 | I16: =IF(ISBLANK($A$2),SUMIFS(Entradas!C:C,Entradas!A:A,'Cadastro-Estoque'!A:A),SUMIFS(Entradas!C:C,Entradas!A:A,'Cadastro-Estoque'!A:A,Entradas!B:B,CONCATENATE("<=",$A$2))) -> 0 | J16: =I16*G16 -> 0 | L16: =IF(ISBLANK($A$2),SUMIFS(Saidas!C:C,Saidas!A:A,'Cadastro-Estoque'!A:A),SUMIFS(Saidas!C:C,Saidas!A:A,'Cadastro-Estoque'!A:A,Saidas!B:B,CONCATENATE("<=",$A$2))) -> 0 | M16: =L16*F16 -> 0 | O16: =IF(ISBLANK($A$2),SUMIFS(Faturado!C:C,Faturado!A:A,'Cadastro-Estoque'!A:A),SUMIFS(Faturado!C:C,Faturado!A:A,'Cadastro-Estoque'!A:A,Faturado!B:B,CONCATENATE("<=",$A$2))) -> 0 | P16: =O16*F16 -> 0 | R16: =IF(ISBLANK($A$2),SUMIFS('PRODUTOS A PRODUZIR'!C:C,'PRODUTOS A PRODUZIR'!A:A,'Cadastro-Estoque'!A:A),SUMIFS('PRODUTOS A PRODUZIR'!C:C,'PRODUTOS A PRODUZIR'!A:A,'Cadastro-Estoque'!A:A,'PRODUTOS A PRODUZIR'!B:B,CONCATENATE("<=",$A$2))) -> 0 | S16: =R16*F16 -> 0
A17: 037 | B17: POLENTA NUTRIVITA 30 X 400 | C17: 30 | D17: 0.4 | E17: 0.405 | F17: =C17*D17 -> 12 | G17: =C17*E17 -> 12.15 | I17: =IF(ISBLANK($A$2),SUMIFS(Entradas!C:C,Entradas!A:A,'Cadastro-Estoque'!A:A),SUMIFS(Entradas!C:C,Entradas!A:A,'Cadastro-Estoque'!A:A,Entradas!B:B,CONCATENATE("<=",$A$2))) -> 0 | J17: =I17*G17 -> 0 | L17: =IF(ISBLANK($A$2),SUMIFS(Saidas!C:C,Saidas!A:A,'Cadastro-Estoque'!A:A),SUMIFS(Saidas!C:C,Saidas!A:A,'Cadastro-Estoque'!A:A,Saidas!B:B,CONCATENATE("<=",$A$2))) -> 0 | M17: =L17*F17 -> 0 | O17: =IF(ISBLANK($A$2),SUMIFS(Faturado!C:C,Faturado!A:A,'Cadastro-Estoque'!A:A),SUMIFS(Faturado!C:C,Faturado!A:A,'Cadastro-Estoque'!A:A,Faturado!B:B,CONCATENATE("<=",$A$2))) -> 0 | P17: =O17*F17 -> 0 | R17: =IF(ISBLANK($A$2),SUMIFS('PRODUTOS A PRODUZIR'!C:C,'PRODUTOS A PRODUZIR'!A:A,'Cadastro-Estoque'!A:A),SUMIFS('PRODUTOS A PRODUZIR'!C:C,'PRODUTOS A PRODUZIR'!A:A,'Cadastro-Estoque'!A:A,'PRODUTOS A PRODUZIR'!B:B,CONCATENATE("<=",$A$2))) -> 0 | S17: =R17*F17 -> 0
A18: 039 | B18: POLENTA CBS 12 X 500 | C18: 12 | D18: 0.5 | E18: 0.505 | F18: =C18*D18 -> 6 | G18: =C18*E18 -> 6.06 | I18: =IF(ISBLANK($A$2),SUMIFS(Entradas!C:C,Entradas!A:A,'Cadastro-Estoque'!A:A),SUMIFS(Entradas!C:C,Entradas!A:A,'Cadastro-Estoque'!A:A,Entradas!B:B,CONCATENATE("<=",$A$2))) -> 0 | J18: =I18*G18 -> 0 | L18: =IF(ISBLANK($A$2),SUMIFS(Saidas!C:C,Saidas!A:A,'Cadastro-Estoque'!A:A),SUMIFS(Saidas!C:C,Saidas!A:A,'Cadastro-Estoque'!A:A,Saidas!B:B,CONCATENATE("<=",$A$2))) -> 0 | M18: =L18*F18 -> 0 | O18: =IF(ISBLANK($A$2),SUMIFS(Faturado!C:C,Faturado!A:A,'Cadastro-Estoque'!A:A),SUMIFS(Faturado!C:C,Faturado!A:A,'Cadastro-Estoque'!A:A,Faturado!B:B,CONCATENATE("<=",$A$2))) -> 0 | P18: =O18*F18 -> 0 | R18: =IF(ISBLANK($A$2),SUMIFS('PRODUTOS A PRODUZIR'!C:C,'PRODUTOS A PRODUZIR'!A:A,'Cadastro-Estoque'!A:A),SUMIFS('PRODUTOS A PRODUZIR'!C:C,'PRODUTOS A PRODUZIR'!A:A,'Cadastro-Estoque'!A:A,'PRODUTOS A PRODUZIR'!B:B,CONCATENATE("<=",$A$2))) -> 0 | S18: =R18*F18 -> 0
A19: 052 | B19: POLENTA FRITZ E FRIDA 12 X 500 | C19: 12 | D19: 0.5 | E19: 0.505 | F19: =C19*D19 -> 6 | G19: =C19*E19 -> 6.06 | I19: =IF(ISBLANK($A$2),SUMIFS(Entradas!C:C,Entradas!A:A,'Cadastro-Estoque'!A:A),SUMIFS(Entradas!C:C,Entradas!A:A,'Cadastro-Estoque'!A:A,Entradas!B:B,CONCATENATE("<=",$A$2))) -> 0 | J19: =I19*G19 -> 0 | L19: =IF(ISBLANK($A$2),SUMIFS(Saidas!C:C,Saidas!A:A,'Cadastro-Estoque'!A:A),SUMIFS(Saidas!C:C,Saidas!A:A,'Cadastro-Estoque'!A:A,Saidas!B:B,CONCATENATE("<=",$A$2))) -> 0 | M19: =L19*F19 -> 0 | O19: =IF(ISBLANK($A$2),SUMIFS(Faturado!C:C,Faturado!A:A,'Cadastro-Estoque'!A:A),SUMIFS(Faturado!C:C,Faturado!A:A,'Cadastro-Estoque'!A:A,Faturado!B:B,CONCATENATE("<=",$A$2))) -> 0 | P19: =O19*F19 -> 0 | R19: =IF(ISBLANK($A$2),SUMIFS('PRODUTOS A PRODUZIR'!C:C,'PRODUTOS A PRODUZIR'!A:A,'Cadastro-Estoque'!A:A),SUMIFS('PRODUTOS A PRODUZIR'!C:C,'PRODUTOS A PRODUZIR'!A:A,'Cadastro-Estoque'!A:A,'PRODUTOS A PRODUZIR'!B:B,CONCATENATE("<=",$A$2))) -> 5610 | S19: =R19*F19 -> 33660
A20: 064 | B20: POLENTA PERDIZ 12 X 1K | C20: 12 | D20: 1 | E20: 1.005 | F20: =C20*D20 -> 12 | G20: =C20*E20 -> 12.06 | I20: =IF(ISBLANK($A$2),SUMIFS(Entradas!C:C,Entradas!A:A,'Cadastro-Estoque'!A:A),SUMIFS(Entradas!C:C,Entradas!A:A,'Cadastro-Estoque'!A:A,Entradas!B:B,CONCATENATE("<=",$A$2))) -> 0 | J20: =I20*G20 -> 0 | L20: =IF(ISBLANK($A$2),SUMIFS(Saidas!C:C,Saidas!A:A,'Cadastro-Estoque'!A:A),SUMIFS(Saidas!C:C,Saidas!A:A,'Cadastro-Estoque'!A:A,Saidas!B:B,CONCATENATE("<=",$A$2))) -> 0 | M20: =L20*F20 -> 0 | O20: =IF(ISBLANK($A$2),SUMIFS(Faturado!C:C,Faturado!A:A,'Cadastro-Estoque'!A:A),SUMIFS(Faturado!C:C,Faturado!A:A,'Cadastro-Estoque'!A:A,Faturado!B:B,CONCATENATE("<=",$A$2))) -> 0 | P20: =O20*F20 -> 0 | R20: =IF(ISBLANK($A$2),SUMIFS('PRODUTOS A PRODUZIR'!C:C,'PRODUTOS A PRODUZIR'!A:A,'Cadastro-Estoque'!A:A),SUMIFS('PRODUTOS A PRODUZIR'!C:C,'PRODUTOS A PRODUZIR'!A:A,'Cadastro-Estoque'!A:A,'PRODUTOS A PRODUZIR'!B:B,CONCATENATE("<=",$A$2))) -> 0 | S20: =R20*F20 -> 0
A21: 064 | B21: POLENTA PERDIZ 12 X 500 G | C21: 12 | D21: 0.5 | E21: 0.505 | F21: =C21*D21 -> 6 | G21: =C21*E21 -> 6.06 | I21: =IF(ISBLANK($A$2),SUMIFS(Entradas!C:C,Entradas!A:A,'Cadastro-Estoque'!A:A),SUMIFS(Entradas!C:C,Entradas!A:A,'Cadastro-Estoque'!A:A,Entradas!B:B,CONCATENATE("<=",$A$2))) -> 0 | J21: =I21*G21 -> 0 | L21: =IF(ISBLANK($A$2),SUMIFS(Saidas!C:C,Saidas!A:A,'Cadastro-Estoque'!A:A),SUMIFS(Saidas!C:C,Saidas!A:A,'Cadastro-Estoque'!A:A,Saidas!B:B,CONCATENATE("<=",$A$2))) -> 0 | M21: =L21*F21 -> 0 | O21: =IF(ISBLANK($A$2),SUMIFS(Faturado!C:C,Faturado!A:A,'Cadastro-Estoque'!A:A),SUMIFS(Faturado!C:C,Faturado!A:A,'Cadastro-Estoque'!A:A,Faturado!B:B,CONCATENATE("<=",$A$2))) -> 0 | P21: =O21*F21 -> 0 | R21: =IF(ISBLANK($A$2),SUMIFS('PRODUTOS A PRODUZIR'!C:C,'PRODUTOS A PRODUZIR'!A:A,'Cadastro-Estoque'!A:A),SUMIFS('PRODUTOS A PRODUZIR'!C:C,'PRODUTOS A PRODUZIR'!A:A,'Cadastro-Estoque'!A:A,'PRODUTOS A PRODUZIR'!B:B,CONCATENATE("<=",$A$2))) -> 0 | S21: =R21*F21 -> 0
A22: 078 | B22: POLENTA BEATRIZ 12 X 500 G | C22: 12 | D22: 0.5 | E22: 0.505 | F22: =C22*D22 -> 6 | G22: =C22*E22 -> 6.06 | I22: =IF(ISBLANK($A$2),SUMIFS(Entradas!C:C,Entradas!A:A,'Cadastro-Estoque'!A:A),SUMIFS(Entradas!C:C,Entradas!A:A,'Cadastro-Estoque'!A:A,Entradas!B:B,CONCATENATE("<=",$A$2))) -> 0 | J22: =I22*G22 -> 0 | L22: =IF(ISBLANK($A$2),SUMIFS(Saidas!C:C,Saidas!A:A,'Cadastro-Estoque'!A:A),SUMIFS(Saidas!C:C,Saidas!A:A,'Cadastro-Estoque'!A:A,Saidas!B:B,CONCATENATE("<=",$A$2))) -> 0 | M22: =L22*F22 -> 0 | O22: =IF(ISBLANK($A$2),SUMIFS(Faturado!C:C,Faturado!A:A,'Cadastro-Estoque'!A:A),SUMIFS(Faturado!C:C,Faturado!A:A,'Cadastro-Estoque'!A:A,Faturado!B:B,CONCATENATE("<=",$A$2))) -> 0 | P22: =O22*F22 -> 0 | R22: =IF(ISBLANK($A$2),SUMIFS('PRODUTOS A PRODUZIR'!C:C,'PRODUTOS A PRODUZIR'!A:A,'Cadastro-Estoque'!A:A),SUMIFS('PRODUTOS A PRODUZIR'!C:C,'PRODUTOS A PRODUZIR'!A:A,'Cadastro-Estoque'!A:A,'PRODUTOS A PRODUZIR'!B:B,CONCATENATE("<=",$A$2))) -> 0 | S22: =R22*F22 -> 0
A23: 079 | B23: POLENTA KISABOR PRÉ COZIDO 24 X 500 | C23: 24 | D23: 0.5 | E23: 0.505 | F23: 12 | G23: =C23*E23 -> 12.12 | I23: =IF(ISBLANK($A$2),SUMIFS(Entradas!C:C,Entradas!A:A,'Cadastro-Estoque'!A:A),SUMIFS(Entradas!C:C,Entradas!A:A,'Cadastro-Estoque'!A:A,Entradas!B:B,CONCATENATE("<=",$A$2))) -> 0 | J23: =I23*G23 -> 0 | L23: =IF(ISBLANK($A$2),SUMIFS(Saidas!C:C,Saidas!A:A,'Cadastro-Estoque'!A:A),SUMIFS(Saidas!C:C,Saidas!A:A,'Cadastro-Estoque'!A:A,Saidas!B:B,CONCATENATE("<=",$A$2))) -> 0 | M23: =L23*F23 -> 0 | O23: =IF(ISBLANK($A$2),SUMIFS(Faturado!C:C,Faturado!A:A,'Cadastro-Estoque'!A:A),SUMIFS(Faturado!C:C,Faturado!A:A,'Cadastro-Estoque'!A:A,Faturado!B:B,CONCATENATE("<=",$A$2))) -> 0 | P23: =O23*F23 -> 0 | R23: =IF(ISBLANK($A$2),SUMIFS('PRODUTOS A PRODUZIR'!C:C,'PRODUTOS A PRODUZIR'!A:A,'Cadastro-Estoque'!A:A),SUMIFS('PRODUTOS A PRODUZIR'!C:C,'PRODUTOS A PRODUZIR'!A:A,'Cadastro-Estoque'!A:A,'PRODUTOS A PRODUZIR'!B:B,CONCATENATE("<=",$A$2))) -> 0 | S23: =R23*F23 -> 0
A24: 084 | B24: FUBÁ PRÉ COZIDO AREPA LAMPIONE 12 X 1 | C24: 12 | D24: 1 | E24: 1.005 | F24: =C24*D24 -> 12 | G24: =C24*E24 -> 12.06 | I24: =IF(ISBLANK($A$2),SUMIFS(Entradas!C:C,Entradas!A:A,'Cadastro-Estoque'!A:A),SUMIFS(Entradas!C:C,Entradas!A:A,'Cadastro-Estoque'!A:A,Entradas!B:B,CONCATENATE("<=",$A$2))) -> 0 | J24: =I24*G24 -> 0 | L24: =IF(ISBLANK($A$2),SUMIFS(Saidas!C:C,Saidas!A:A,'Cadastro-Estoque'!A:A),SUMIFS(Saidas!C:C,Saidas!A:A,'Cadastro-Estoque'!A:A,Saidas!B:B,CONCATENATE("<=",$A$2))) -> 0 | M24: =L24*F24 -> 0 | O24: =IF(ISBLANK($A$2),SUMIFS(Faturado!C:C,Faturado!A:A,'Cadastro-Estoque'!A:A),SUMIFS(Faturado!C:C,Faturado!A:A,'Cadastro-Estoque'!A:A,Faturado!B:B,CONCATENATE("<=",$A$2))) -> 0 | P24: =O24*F24 -> 0 | R24: =IF(ISBLANK($A$2),SUMIFS('PRODUTOS A PRODUZIR'!C:C,'PRODUTOS A PRODUZIR'!A:A,'Cadastro-Estoque'!A:A),SUMIFS('PRODUTOS A PRODUZIR'!C:C,'PRODUTOS A PRODUZIR'!A:A,'Cadastro-Estoque'!A:A,'PRODUTOS A PRODUZIR'!B:B,CONCATENATE("<=",$A$2))) -> 0 | S24: =R24*F24 -> 0
A25: 092 | B25: FUBÁ PRÉ COZIDO AREPA NUTRIVITA 12 X 1 | C25: 12 | D25: 1 | E25: 1.005 | F25: =C25*D25 -> 12 | G25: =C25*E25 -> 12.06 | I25: =IF(ISBLANK($A$2),SUMIFS(Entradas!C:C,Entradas!A:A,'Cadastro-Estoque'!A:A),SUMIFS(Entradas!C:C,Entradas!A:A,'Cadastro-Estoque'!A:A,Entradas!B:B,CONCATENATE("<=",$A$2))) -> 0 | J25: =I25*G25 -> 0 | L25: =IF(ISBLANK($A$2),SUMIFS(Saidas!C:C,Saidas!A:A,'Cadastro-Estoque'!A:A),SUMIFS(Saidas!C:C,Saidas!A:A,'Cadastro-Estoque'!A:A,Saidas!B:B,CONCATENATE("<=",$A$2))) -> 0 | M25: =L25*F25 -> 0 | O25: =IF(ISBLANK($A$2),SUMIFS(Faturado!C:C,Faturado!A:A,'Cadastro-Estoque'!A:A),SUMIFS(Faturado!C:C,Faturado!A:A,'Cadastro-Estoque'!A:A,Faturado!B:B,CONCATENATE("<=",$A$2))) -> 0 | P25: =O25*F25 -> 0 | R25: =IF(ISBLANK($A$2),SUMIFS('PRODUTOS A PRODUZIR'!C:C,'PRODUTOS A PRODUZIR'!A:A,'Cadastro-Estoque'!A:A),SUMIFS('PRODUTOS A PRODUZIR'!C:C,'PRODUTOS A PRODUZIR'!A:A,'Cadastro-Estoque'!A:A,'PRODUTOS A PRODUZIR'!B:B,CONCATENATE("<=",$A$2))) -> 0 | S25: =R25*F25 -> 0
A26: 092 | B26: FUBÁ PRÉ COZIDO AREPA NUTRIVITA 30 X 500 | C26: 30 | D26: 0.5 | E26: 0.505 | F26: =C26*D26 -> 15 | G26: =C26*E26 -> 15.15 | I26: =IF(ISBLANK($A$2),SUMIFS(Entradas!C:C,Entradas!A:A,'Cadastro-Estoque'!A:A),SUMIFS(Entradas!C:C,Entradas!A:A,'Cadastro-Estoque'!A:A,Entradas!B:B,CONCATENATE("<=",$A$2))) -> 0 | J26: =I26*G26 -> 0 | L26: =IF(ISBLANK($A$2),SUMIFS(Saidas!C:C,Saidas!A:A,'Cadastro-Estoque'!A:A),SUMIFS(Saidas!C:C,Saidas!A:A,'Cadastro-Estoque'!A:A,Saidas!B:B,CONCATENATE("<=",$A$2))) -> 0 | M26: =L26*F26 -> 0 | O26: =IF(ISBLANK($A$2),SUMIFS(Faturado!C:C,Faturado!A:A,'Cadastro-Estoque'!A:A),SUMIFS(Faturado!C:C,Faturado!A:A,'Cadastro-Estoque'!A:A,Faturado!B:B,CONCATENATE("<=",$A$2))) -> 0 | P26: =O26*F26 -> 0 | R26: =IF(ISBLANK($A$2),SUMIFS('PRODUTOS A PRODUZIR'!C:C,'PRODUTOS A PRODUZIR'!A:A,'Cadastro-Estoque'!A:A),SUMIFS('PRODUTOS A PRODUZIR'!C:C,'PRODUTOS A PRODUZIR'!A:A,'Cadastro-Estoque'!A:A,'PRODUTOS A PRODUZIR'!B:B,CONCATENATE("<=",$A$2))) -> 0 | S26: =R26*F26 -> 0
A27: 095 | B27: FUBÁ PRÉ COZIDO BOA NOVA 30 X 500 | C27: 30 | D27: 0.5 | E27: 0.505 | F27: =C27*D27 -> 15 | G27: =C27*E27 -> 15.15 | I27: =IF(ISBLANK($A$2),SUMIFS(Entradas!C:C,Entradas!A:A,'Cadastro-Estoque'!A:A),SUMIFS(Entradas!C:C,Entradas!A:A,'Cadastro-Estoque'!A:A,Entradas!B:B,CONCATENATE("<=",$A$2))) -> 0 | J27: =I27*G27 -> 0 | L27: =IF(ISBLANK($A$2),SUMIFS(Saidas!C:C,Saidas!A:A,'Cadastro-Estoque'!A:A),SUMIFS(Saidas!C:C,Saidas!A:A,'Cadastro-Estoque'!A:A,Saidas!B:B,CONCATENATE("<=",$A$2))) -> 0 | M27: =L27*F27 -> 0 | O27: =IF(ISBLANK($A$2),SUMIFS(Faturado!C:C,Faturado!A:A,'Cadastro-Estoque'!A:A),SUMIFS(Faturado!C:C,Faturado!A:A,'Cadastro-Estoque'!A:A,Faturado!B:B,CONCATENATE("<=",$A$2))) -> 0 | P27: =O27*F27 -> 0 | R27: =IF(ISBLANK($A$2),SUMIFS('PRODUTOS A PRODUZIR'!C:C,'PRODUTOS A PRODUZIR'!A:A,'Cadastro-Estoque'!A:A),SUMIFS('PRODUTOS A PRODUZIR'!C:C,'PRODUTOS A PRODUZIR'!A:A,'Cadastro-Estoque'!A:A,'PRODUTOS A PRODUZIR'!B:B,CONCATENATE("<=",$A$2))) -> 0 | S27: =R27*F27 -> 0
A28: 098 | B28: FUBÁ PRÉ COZIDO AREPA REINAREPA 12 X 1 | C28: 12 | D28: 1 | E28: 1.005 | F28: =C28*D28 -> 12 | G28: =C28*E28 -> 12.06 | I28: =IF(ISBLANK($A$2),SUMIFS(Entradas!C:C,Entradas!A:A,'Cadastro-Estoque'!A:A),SUMIFS(Entradas!C:C,Entradas!A:A,'Cadastro-Estoque'!A:A,Entradas!B:B,CONCATENATE("<=",$A$2))) -> 0 | J28: =I28*G28 -> 0 | L28: =IF(ISBLANK($A$2),SUMIFS(Saidas!C:C,Saidas!A:A,'Cadastro-Estoque'!A:A),SUMIFS(Saidas!C:C,Saidas!A:A,'Cadastro-Estoque'!A:A,Saidas!B:B,CONCATENATE("<=",$A$2))) -> 0 | M28: =L28*F28 -> 0 | O28: =IF(ISBLANK($A$2),SUMIFS(Faturado!C:C,Faturado!A:A,'Cadastro-Estoque'!A:A),SUMIFS(Faturado!C:C,Faturado!A:A,'Cadastro-Estoque'!A:A,Faturado!B:B,CONCATENATE("<=",$A$2))) -> 0 | P28: =O28*F28 -> 0 | R28: =IF(ISBLANK($A$2),SUMIFS('PRODUTOS A PRODUZIR'!C:C,'PRODUTOS A PRODUZIR'!A:A,'Cadastro-Estoque'!A:A),SUMIFS('PRODUTOS A PRODUZIR'!C:C,'PRODUTOS A PRODUZIR'!A:A,'Cadastro-Estoque'!A:A,'PRODUTOS A PRODUZIR'!B:B,CONCATENATE("<=",$A$2))) -> 0 | S28: =R28*F28 -> 0
A29: 098 | B29: FUBÁ PRÉ COZIDO AREPA REINAREPA 30 x 500 | C29: 30 | D29: 0.5 | E29: 0.505 | F29: =C29*D29 -> 15 | G29: =C29*E29 -> 15.15 | I29: =IF(ISBLANK($A$2),SUMIFS(Entradas!C:C,Entradas!A:A,'Cadastro-Estoque'!A:A),SUMIFS(Entradas!C:C,Entradas!A:A,'Cadastro-Estoque'!A:A,Entradas!B:B,CONCATENATE("<=",$A$2))) -> 0 | J29: =I29*G29 -> 0 | L29: =IF(ISBLANK($A$2),SUMIFS(Saidas!C:C,Saidas!A:A,'Cadastro-Estoque'!A:A),SUMIFS(Saidas!C:C,Saidas!A:A,'Cadastro-Estoque'!A:A,Saidas!B:B,CONCATENATE("<=",$A$2))) -> 0 | M29: =L29*F29 -> 0 | O29: =IF(ISBLANK($A$2),SUMIFS(Faturado!C:C,Faturado!A:A,'Cadastro-Estoque'!A:A),SUMIFS(Faturado!C:C,Faturado!A:A,'Cadastro-Estoque'!A:A,Faturado!B:B,CONCATENATE("<=",$A$2))) -> 0 | P29: =O29*F29 -> 0 | R29: =IF(ISBLANK($A$2),SUMIFS('PRODUTOS A PRODUZIR'!C:C,'PRODUTOS A PRODUZIR'!A:A,'Cadastro-Estoque'!A:A),SUMIFS('PRODUTOS A PRODUZIR'!C:C,'PRODUTOS A PRODUZIR'!A:A,'Cadastro-Estoque'!A:A,'PRODUTOS A PRODUZIR'!B:B,CONCATENATE("<=",$A$2))) -> 0 | S29: =R29*F29 -> 0
A30: 100 | B30: POLENTA TUPÃ PRE COZIDO 30 X 500 | C30: 30 | D30: 0.5 | E30: 0.505 | F30: =C30*D30 -> 15 | G30: =C30*E30 -> 15.15 | I30: =IF(ISBLANK($A$2),SUMIFS(Entradas!C:C,Entradas!A:A,'Cadastro-Estoque'!A:A),SUMIFS(Entradas!C:C,Entradas!A:A,'Cadastro-Estoque'!A:A,Entradas!B:B,CONCATENATE("<=",$A$2))) -> 0 | J30: =I30*G30 -> 0 | L30: =IF(ISBLANK($A$2),SUMIFS(Saidas!C:C,Saidas!A:A,'Cadastro-Estoque'!A:A),SUMIFS(Saidas!C:C,Saidas!A:A,'Cadastro-Estoque'!A:A,Saidas!B:B,CONCATENATE("<=",$A$2))) -> 0 | M30: =L30*F30 -> 0 | O30: =IF(ISBLANK($A$2),SUMIFS(Faturado!C:C,Faturado!A:A,'Cadastro-Estoque'!A:A),SUMIFS(Faturado!C:C,Faturado!A:A,'Cadastro-Estoque'!A:A,Faturado!B:B,CONCATENATE("<=",$A$2))) -> 0 | P30: =O30*F30 -> 0 | R30: =IF(ISBLANK($A$2),SUMIFS('PRODUTOS A PRODUZIR'!C:C,'PRODUTOS A PRODUZIR'!A:A,'Cadastro-Estoque'!A:A),SUMIFS('PRODUTOS A PRODUZIR'!C:C,'PRODUTOS A PRODUZIR'!A:A,'Cadastro-Estoque'!A:A,'PRODUTOS A PRODUZIR'!B:B,CONCATENATE("<=",$A$2))) -> 0 | S30: =R30*F30 -> 0
A31: 105 | B31: FUBÁ PRÉ COZIDO AREPITA CARIBE 30 x 500 | C31: 30 | D31: 0.5 | E31: 0.505 | F31: =C31*D31 -> 15 | G31: =C31*E31 -> 15.15 | I31: =IF(ISBLANK($A$2),SUMIFS(Entradas!C:C,Entradas!A:A,'Cadastro-Estoque'!A:A),SUMIFS(Entradas!C:C,Entradas!A:A,'Cadastro-Estoque'!A:A,Entradas!B:B,CONCATENATE("<=",$A$2))) -> 0 | J31: =I31*G31 -> 0 | L31: =IF(ISBLANK($A$2),SUMIFS(Saidas!C:C,Saidas!A:A,'Cadastro-Estoque'!A:A),SUMIFS(Saidas!C:C,Saidas!A:A,'Cadastro-Estoque'!A:A,Saidas!B:B,CONCATENATE("<=",$A$2))) -> 0 | M31: =L31*F31 -> 0 | O31: =IF(ISBLANK($A$2),SUMIFS(Faturado!C:C,Faturado!A:A,'Cadastro-Estoque'!A:A),SUMIFS(Faturado!C:C,Faturado!A:A,'Cadastro-Estoque'!A:A,Faturado!B:B,CONCATENATE("<=",$A$2))) -> 0 | P31: =O31*F31 -> 0 | R31: =IF(ISBLANK($A$2),SUMIFS('PRODUTOS A PRODUZIR'!C:C,'PRODUTOS A PRODUZIR'!A:A,'Cadastro-Estoque'!A:A),SUMIFS('PRODUTOS A PRODUZIR'!C:C,'PRODUTOS A PRODUZIR'!A:A,'Cadastro-Estoque'!A:A,'PRODUTOS A PRODUZIR'!B:B,CONCATENATE("<=",$A$2))) -> 0 | S31: =R31*F31 -> 0
I32: =IF(ISBLANK($A$2),SUMIFS(Entradas!C:C,Entradas!A:A,'Cadastro-Estoque'!A:A),SUMIFS(Entradas!C:C,Entradas!A:A,'Cadastro-Estoque'!A:A,Entradas!B:B,CONCATENATE("<=",$A$2))) -> 0 | J32: =I32*G32 -> 0 | L32: =IF(ISBLANK($A$2),SUMIFS(Saidas!C:C,Saidas!A:A,'Cadastro-Estoque'!A:A),SUMIFS(Saidas!C:C,Saidas!A:A,'Cadastro-Estoque'!A:A,Saidas!B:B,CONCATENATE("<=",$A$2))) -> 0 | M32: =L32*F32 -> 0 | O32: =IF(ISBLANK($A$2),SUMIFS(Faturado!C:C,Faturado!A:A,'Cadastro-Estoque'!A:A),SUMIFS(Faturado!C:C,Faturado!A:A,'Cadastro-Estoque'!A:A,Faturado!B:B,CONCATENATE("<=",$A$2))) -> 0 | P32: =O32*F32 -> 0 | R32: =IF(ISBLANK($A$2),SUMIFS('PRODUTOS A PRODUZIR'!C:C,'PRODUTOS A PRODUZIR'!A:A,'Cadastro-Estoque'!A:A),SUMIFS('PRODUTOS A PRODUZIR'!C:C,'PRODUTOS A PRODUZIR'!A:A,'Cadastro-Estoque'!A:A,'PRODUTOS A PRODUZIR'!B:B,CONCATENATE("<=",$A$2))) -> 0 | S32: =R32*F32 -> 0
A33: 201 | B33: FLOÇÃO MILHO NUTRIVITA 20 X 500 | C33: 20 | D33: 0.5 | E33: 0.505 | F33: =C33*D33 -> 10 | G33: =C33*E33 -> 10.1 | I33: =IF(ISBLANK($A$2),SUMIFS(Entradas!C:C,Entradas!A:A,'Cadastro-Estoque'!A:A),SUMIFS(Entradas!C:C,Entradas!A:A,'Cadastro-Estoque'!A:A,Entradas!B:B,CONCATENATE("<=",$A$2))) -> 1841 | J33: =I33*G33 -> 18594.1 | L33: =IF(ISBLANK($A$2),SUMIFS(Saidas!C:C,Saidas!A:A,'Cadastro-Estoque'!A:A),SUMIFS(Saidas!C:C,Saidas!A:A,'Cadastro-Estoque'!A:A,Saidas!B:B,CONCATENATE("<=",$A$2))) -> 1668 | M33: =L33*F33 -> 16680 | O33: =IF(ISBLANK($A$2),SUMIFS(Faturado!C:C,Faturado!A:A,'Cadastro-Estoque'!A:A),SUMIFS(Faturado!C:C,Faturado!A:A,'Cadastro-Estoque'!A:A,Faturado!B:B,CONCATENATE("<=",$A$2))) -> 0 | P33: =O33*F33 -> 0 | R33: =IF(ISBLANK($A$2),SUMIFS('PRODUTOS A PRODUZIR'!C:C,'PRODUTOS A PRODUZIR'!A:A,'Cadastro-Estoque'!A:A),SUMIFS('PRODUTOS A PRODUZIR'!C:C,'PRODUTOS A PRODUZIR'!A:A,'Cadastro-Estoque'!A:A,'PRODUTOS A PRODUZIR'!B:B,CONCATENATE("<=",$A$2))) -> 0 | S33: =R33*F33 -> 0
A34: 201 | B34: FLOÇÃO MILHO NUTRIVITA 10 X 500 | C34: 10 | D34: 0.5 | E34: 0.505 | F34: =C34*D34 -> 5 | G34: =C34*E34 -> 5.05 | I34: =IF(ISBLANK($A$2),SUMIFS(Entradas!C:C,Entradas!A:A,'Cadastro-Estoque'!A:A),SUMIFS(Entradas!C:C,Entradas!A:A,'Cadastro-Estoque'!A:A,Entradas!B:B,CONCATENATE("<=",$A$2))) -> 0 | J34: =I34*G34 -> 0 | L34: =IF(ISBLANK($A$2),SUMIFS(Saidas!C:C,Saidas!A:A,'Cadastro-Estoque'!A:A),SUMIFS(Saidas!C:C,Saidas!A:A,'Cadastro-Estoque'!A:A,Saidas!B:B,CONCATENATE("<=",$A$2))) -> 0 | M34: =L34*F34 -> 0 | O34: =IF(ISBLANK($A$2),SUMIFS(Faturado!C:C,Faturado!A:A,'Cadastro-Estoque'!A:A),SUMIFS(Faturado!C:C,Faturado!A:A,'Cadastro-Estoque'!A:A,Faturado!B:B,CONCATENATE("<=",$A$2))) -> 0 | P34: =O34*F34 -> 0 | R34: =IF(ISBLANK($A$2),SUMIFS('PRODUTOS A PRODUZIR'!C:C,'PRODUTOS A PRODUZIR'!A:A,'Cadastro-Estoque'!A:A),SUMIFS('PRODUTOS A PRODUZIR'!C:C,'PRODUTOS A PRODUZIR'!A:A,'Cadastro-Estoque'!A:A,'PRODUTOS A PRODUZIR'!B:B,CONCATENATE("<=",$A$2))) -> 0 | S34: =R34*F34 -> 0
A35: 205 | B35: FLOÇÃO MILHO VITABEM 20 X 500 | C35: 20 | D35: 0.5 | E35: 0.505 | F35: =C35*D35 -> 10 | G35: =C35*E35 -> 10.1 | I35: =IF(ISBLANK($A$2),SUMIFS(Entradas!C:C,Entradas!A:A,'Cadastro-Estoque'!A:A),SUMIFS(Entradas!C:C,Entradas!A:A,'Cadastro-Estoque'!A:A,Entradas!B:B,CONCATENATE("<=",$A$2))) -> 0 | J35: =I35*G35 -> 0 | L35: =IF(ISBLANK($A$2),SUMIFS(Saidas!C:C,Saidas!A:A,'Cadastro-Estoque'!A:A),SUMIFS(Saidas!C:C,Saidas!A:A,'Cadastro-Estoque'!A:A,Saidas!B:B,CONCATENATE("<=",$A$2))) -> 0 | M35: =L35*F35 -> 0 | O35: =IF(ISBLANK($A$2),SUMIFS(Faturado!C:C,Faturado!A:A,'Cadastro-Estoque'!A:A),SUMIFS(Faturado!C:C,Faturado!A:A,'Cadastro-Estoque'!A:A,Faturado!B:B,CONCATENATE("<=",$A$2))) -> 0 | P35: =O35*F35 -> 0 | R35: =IF(ISBLANK($A$2),SUMIFS('PRODUTOS A PRODUZIR'!C:C,'PRODUTOS A PRODUZIR'!A:A,'Cadastro-Estoque'!A:A),SUMIFS('PRODUTOS A PRODUZIR'!C:C,'PRODUTOS A PRODUZIR'!A:A,'Cadastro-Estoque'!A:A,'PRODUTOS A PRODUZIR'!B:B,CONCATENATE("<=",$A$2))) -> 0 | S35: =R35*F35 -> 0
A36: 207 | B36: FLOÇÃO MILHO VITABRAS 20 X 400 | C36: 20 | D36: 0.4 | E36: 0.404 | F36: =C36*D36 -> 8 | G36: =C36*E36 -> 8.08 | I36: =IF(ISBLANK($A$2),SUMIFS(Entradas!C:C,Entradas!A:A,'Cadastro-Estoque'!A:A),SUMIFS(Entradas!C:C,Entradas!A:A,'Cadastro-Estoque'!A:A,Entradas!B:B,CONCATENATE("<=",$A$2))) -> 0 | J36: =I36*G36 -> 0 | L36: =IF(ISBLANK($A$2),SUMIFS(Saidas!C:C,Saidas!A:A,'Cadastro-Estoque'!A:A),SUMIFS(Saidas!C:C,Saidas!A:A,'Cadastro-Estoque'!A:A,Saidas!B:B,CONCATENATE("<=",$A$2))) -> 0 | M36: =L36*F36 -> 0 | O36: =IF(ISBLANK($A$2),SUMIFS(Faturado!C:C,Faturado!A:A,'Cadastro-Estoque'!A:A),SUMIFS(Faturado!C:C,Faturado!A:A,'Cadastro-Estoque'!A:A,Faturado!B:B,CONCATENATE("<=",$A$2))) -> 0 | P36: =O36*F36 -> 0 | R36: =IF(ISBLANK($A$2),SUMIFS('PRODUTOS A PRODUZIR'!C:C,'PRODUTOS A PRODUZIR'!A:A,'Cadastro-Estoque'!A:A),SUMIFS('PRODUTOS A PRODUZIR'!C:C,'PRODUTOS A PRODUZIR'!A:A,'Cadastro-Estoque'!A:A,'PRODUTOS A PRODUZIR'!B:B,CONCATENATE("<=",$A$2))) -> 0 | S36: =R36*F36 -> 0
A37: 208 | B37: FLOÇÃO MILHO PURO MILHO 12 X 500 | C37: 12 | D37: 0.5 | E37: 0.505 | F37: =C37*D37 -> 6 | G37: =C37*E37 -> 6.06 | I37: =IF(ISBLANK($A$2),SUMIFS(Entradas!C:C,Entradas!A:A,'Cadastro-Estoque'!A:A),SUMIFS(Entradas!C:C,Entradas!A:A,'Cadastro-Estoque'!A:A,Entradas!B:B,CONCATENATE("<=",$A$2))) -> 0 | J37: =I37*G37 -> 0 | L37: =IF(ISBLANK($A$2),SUMIFS(Saidas!C:C,Saidas!A:A,'Cadastro-Estoque'!A:A),SUMIFS(Saidas!C:C,Saidas!A:A,'Cadastro-Estoque'!A:A,Saidas!B:B,CONCATENATE("<=",$A$2))) -> 10400 | M37: =L37*F37 -> 62400 | O37: =IF(ISBLANK($A$2),SUMIFS(Faturado!C:C,Faturado!A:A,'Cadastro-Estoque'!A:A),SUMIFS(Faturado!C:C,Faturado!A:A,'Cadastro-Estoque'!A:A,Faturado!B:B,CONCATENATE("<=",$A$2))) -> 0 | P37: =O37*F37 -> 0 | R37: =IF(ISBLANK($A$2),SUMIFS('PRODUTOS A PRODUZIR'!C:C,'PRODUTOS A PRODUZIR'!A:A,'Cadastro-Estoque'!A:A),SUMIFS('PRODUTOS A PRODUZIR'!C:C,'PRODUTOS A PRODUZIR'!A:A,'Cadastro-Estoque'!A:A,'PRODUTOS A PRODUZIR'!B:B,CONCATENATE("<=",$A$2))) -> 0 | S37: =R37*F37 -> 0
A38: 209 | B38: FLOCÃO DE MILHO QUALITÁ 12 X 500 | C38: 12 | D38: 0.5 | E38: 0.505 | F38: =C38*D38 -> 6 | G38: =C38*E38 -> 6.06 | I38: =IF(ISBLANK($A$2),SUMIFS(Entradas!C:C,Entradas!A:A,'Cadastro-Estoque'!A:A),SUMIFS(Entradas!C:C,Entradas!A:A,'Cadastro-Estoque'!A:A,Entradas!B:B,CONCATENATE("<=",$A$2))) -> 0 | J38: =I38*G38 -> 0 | L38: =IF(ISBLANK($A$2),SUMIFS(Saidas!C:C,Saidas!A:A,'Cadastro-Estoque'!A:A),SUMIFS(Saidas!C:C,Saidas!A:A,'Cadastro-Estoque'!A:A,Saidas!B:B,CONCATENATE("<=",$A$2))) -> 0 | M38: =L38*F38 -> 0 | O38: =IF(ISBLANK($A$2),SUMIFS(Faturado!C:C,Faturado!A:A,'Cadastro-Estoque'!A:A),SUMIFS(Faturado!C:C,Faturado!A:A,'Cadastro-Estoque'!A:A,Faturado!B:B,CONCATENATE("<=",$A$2))) -> 0 | P38: =O38*F38 -> 0 | R38: =IF(ISBLANK($A$2),SUMIFS('PRODUTOS A PRODUZIR'!C:C,'PRODUTOS A PRODUZIR'!A:A,'Cadastro-Estoque'!A:A),SUMIFS('PRODUTOS A PRODUZIR'!C:C,'PRODUTOS A PRODUZIR'!A:A,'Cadastro-Estoque'!A:A,'PRODUTOS A PRODUZIR'!B:B,CONCATENATE("<=",$A$2))) -> 0 | S38: =R38*F38 -> 0
A39: 212 | B39: FLOCAO DE MILHO LESTE 20 X 500 | C39: 20 | D39: 0.5 | E39: 0.505 | F39: =C39*D39 -> 10 | G39: =C39*E39 -> 10.1 | I39: =IF(ISBLANK($A$2),SUMIFS(Entradas!C:C,Entradas!A:A,'Cadastro-Estoque'!A:A),SUMIFS(Entradas!C:C,Entradas!A:A,'Cadastro-Estoque'!A:A,Entradas!B:B,CONCATENATE("<=",$A$2))) -> 0 | J39: =I39*G39 -> 0 | L39: =IF(ISBLANK($A$2),SUMIFS(Saidas!C:C,Saidas!A:A,'Cadastro-Estoque'!A:A),SUMIFS(Saidas!C:C,Saidas!A:A,'Cadastro-Estoque'!A:A,Saidas!B:B,CONCATENATE("<=",$A$2))) -> 0 | M39: =L39*F39 -> 0 | O39: =IF(ISBLANK($A$2),SUMIFS(Faturado!C:C,Faturado!A:A,'Cadastro-Estoque'!A:A),SUMIFS(Faturado!C:C,Faturado!A:A,'Cadastro-Estoque'!A:A,Faturado!B:B,CONCATENATE("<=",$A$2))) -> 0 | P39: =O39*F39 -> 0 | R39: =IF(ISBLANK($A$2),SUMIFS('PRODUTOS A PRODUZIR'!C:C,'PRODUTOS A PRODUZIR'!A:A,'Cadastro-Estoque'!A:A),SUMIFS('PRODUTOS A PRODUZIR'!C:C,'PRODUTOS A PRODUZIR'!A:A,'Cadastro-Estoque'!A:A,'PRODUTOS A PRODUZIR'!B:B,CONCATENATE("<=",$A$2))) -> 0 | S39: =R39*F39 -> 0
A40: 216 | B40: FLOÇÃO MILHO M & K 12 X 500 | C40: 12 | D40: 0.5 | E40: 0.505 | F40: =C40*D40 -> 6 | G40: =C40*E40 -> 6.06 | I40: =IF(ISBLANK($A$2),SUMIFS(Entradas!C:C,Entradas!A:A,'Cadastro-Estoque'!A:A),SUMIFS(Entradas!C:C,Entradas!A:A,'Cadastro-Estoque'!A:A,Entradas!B:B,CONCATENATE("<=",$A$2))) -> 0 | J40: =I40*G40 -> 0 | L40: =IF(ISBLANK($A$2),SUMIFS(Saidas!C:C,Saidas!A:A,'Cadastro-Estoque'!A:A),SUMIFS(Saidas!C:C,Saidas!A:A,'Cadastro-Estoque'!A:A,Saidas!B:B,CONCATENATE("<=",$A$2))) -> 0 | M40: =L40*F40 -> 0 | O40: =IF(ISBLANK($A$2),SUMIFS(Faturado!C:C,Faturado!A:A,'Cadastro-Estoque'!A:A),SUMIFS(Faturado!C:C,Faturado!A:A,'Cadastro-Estoque'!A:A,Faturado!B:B,CONCATENATE("<=",$A$2))) -> 0 | P40: =O40*F40 -> 0 | R40: =IF(ISBLANK($A$2),SUMIFS('PRODUTOS A PRODUZIR'!C:C,'PRODUTOS A PRODUZIR'!A:A,'Cadastro-Estoque'!A:A),SUMIFS('PRODUTOS A PRODUZIR'!C:C,'PRODUTOS A PRODUZIR'!A:A,'Cadastro-Estoque'!A:A,'PRODUTOS A PRODUZIR'!B:B,CONCATENATE("<=",$A$2))) -> 0 | S40: =R40*F40 -> 0
A41: 218 | B41: FLOÇÃO MILHO CBS 12 X 500 | C41: 12 | D41: 0.5 | E41: 0.505 | F41: =C41*D41 -> 6 | G41: =C41*E41 -> 6.06 | I41: =IF(ISBLANK($A$2),SUMIFS(Entradas!C:C,Entradas!A:A,'Cadastro-Estoque'!A:A),SUMIFS(Entradas!C:C,Entradas!A:A,'Cadastro-Estoque'!A:A,Entradas!B:B,CONCATENATE("<=",$A$2))) -> 0 | J41: =I41*G41 -> 0 | L41: =IF(ISBLANK($A$2),SUMIFS(Saidas!C:C,Saidas!A:A,'Cadastro-Estoque'!A:A),SUMIFS(Saidas!C:C,Saidas!A:A,'Cadastro-Estoque'!A:A,Saidas!B:B,CONCATENATE("<=",$A$2))) -> 0 | M41: =L41*F41 -> 0 | O41: =IF(ISBLANK($A$2),SUMIFS(Faturado!C:C,Faturado!A:A,'Cadastro-Estoque'!A:A),SUMIFS(Faturado!C:C,Faturado!A:A,'Cadastro-Estoque'!A:A,Faturado!B:B,CONCATENATE("<=",$A$2))) -> 0 | P41: =O41*F41 -> 0 | R41: =IF(ISBLANK($A$2),SUMIFS('PRODUTOS A PRODUZIR'!C:C,'PRODUTOS A PRODUZIR'!A:A,'Cadastro-Estoque'!A:A),SUMIFS('PRODUTOS A PRODUZIR'!C:C,'PRODUTOS A PRODUZIR'!A:A,'Cadastro-Estoque'!A:A,'PRODUTOS A PRODUZIR'!B:B,CONCATENATE("<=",$A$2))) -> 0 | S41: =R41*F41 -> 0
...

Sheet Cadastro-Estoque
A1: Planilha de Controle de Estoque
A2: Data do estoque:
A3: Código | B3: Descrição | C3: Unidade | D3: Fornecedor | E3: Mínimo | F3: Saldo Inicial | G3: Estoque atual | H3: Média Entrada(R$) | I3: Média Saída(R$) | K3: ESTOQUE PAULO
A4: 011-12X500 | B4: FLOCADO NUTRIVITA 12 X 500 | C4: FARDOS | D4: ADRAM | F4: 0 | G4: =IF(ISBLANK($G$2),SUMIFS(Entradas!C:C,Entradas!A:A,'Cadastro-Estoque'!A:A)-SUMIFS(Saidas!C:C,Saidas!A:A,'Cadastro-Estoque'!A:A),SUMIFS(Entradas!C:C,Entradas!A:A,'Cadastro-Estoque'!A:A,Entradas!B:B,CONCATENATE("<=",$G$2))-SUMIFS(Saidas!C:C,Saidas!A:A,'Cadastro-Estoque'!A:A,Saidas!B:B,CONCATENATE("<=",$G$2)))+F4 -> 0 | H4: 0 | I4: =IF(ISBLANK($G$2),SUMIFS(Saidas!E:E,Saidas!A:A,'Cadastro-Estoque'!A:A),SUMIFS(Saidas!E:E,Saidas!A:A,'Cadastro-Estoque'!A:A,Saidas!B:B,CONCATENATE("<=",$G$2)))/IF(IF(ISBLANK($G$2),SUMIFS(Saidas!C:C,Saidas!A:A,'Cadastro-Estoque'!A:A),SUMIFS(Saidas!C:C,Saidas!A:A,'Cadastro-Estoque'!A:A,Saidas!B:B,CONCATENATE("<=",$G$2)))=0,1,IF(ISBLANK($G$2),SUMIFS(Saidas!C:C,Saidas!A:A,'Cadastro-Estoque'!A:A),SUMIFS(Saidas!C:C,Saidas!A:A,'Cadastro-Estoque'!A:A,Saidas!B:B,CONCATENATE("<=",$G$2)))) -> 0 | K4: =#REF! -> #REF!
A5: 011-30X500 | B5: FLOCADO NUTRIVITA 30 X 500 | C5: FARDOS | D5: ADRAM | F5: 38185 | G5: =IF(ISBLANK($G$2),SUMIFS(Entradas!C:C,Entradas!A:A,'Cadastro-Estoque'!A:A)-SUMIFS(Saidas!C:C,Saidas!A:A,'Cadastro-Estoque'!A:A),SUMIFS(Entradas!C:C,Entradas!A:A,'Cadastro-Estoque'!A:A,Entradas!B:B,CONCATENATE("<=",$G$2))-SUMIFS(Saidas!C:C,Saidas!A:A,'Cadastro-Estoque'!A:A,Saidas!B:B,CONCATENATE("<=",$G$2)))+F5 -> 34796 | H5: 24.3 | I5: =IF(ISBLANK($G$2),SUMIFS(Saidas!E:E,Saidas!A:A,'Cadastro-Estoque'!A:A),SUMIFS(Saidas!E:E,Saidas!A:A,'Cadastro-Estoque'!A:A,Saidas!B:B,CONCATENATE("<=",$G$2)))/IF(IF(ISBLANK($G$2),SUMIFS(Saidas!C:C,Saidas!A:A,'Cadastro-Estoque'!A:A),SUMIFS(Saidas!C:C,Saidas!A:A,'Cadastro-Estoque'!A:A,Saidas!B:B,CONCATENATE("<=",$G$2)))=0,1,IF(ISBLANK($G$2),SUMIFS(Saidas!C:C,Saidas!A:A,'Cadastro-Estoque'!A:A),SUMIFS(Saidas!C:C,Saidas!A:A,'Cadastro-Estoque'!A:A,Saidas!B:B,CONCATENATE("<=",$G$2)))) -> 0 | K5: =#REF! -> #REF!
A6: 012-30X500 | B6: FLOCADO VITABEM 30 X 500 | C6: FARDOS | D6: ADRAM | F6: 365 | G6: =IF(ISBLANK($G$2),SUMIFS(Entradas!C:C,Entradas!A:A,'Cadastro-Estoque'!A:A)-SUMIFS(Saidas!C:C,Saidas!A:A,'Cadastro-Estoque'!A:A),SUMIFS(Entradas!C:C,Entradas!A:A,'Cadastro-Estoque'!A:A,Entradas!B:B,CONCATENATE("<=",$G$2))-SUMIFS(Saidas!C:C,Saidas!A:A,'Cadastro-Estoque'!A:A,Saidas!B:B,CONCATENATE("<=",$G$2)))+F6 -> 365 | H6: 23.5 | I6: =IF(ISBLANK($G$2),SUMIFS(Saidas!E:E,Saidas!A:A,'Cadastro-Estoque'!A:A),SUMIFS(Saidas!E:E,Saidas!A:A,'Cadastro-Estoque'!A:A,Saidas!B:B,CONCATENATE("<=",$G$2)))/IF(IF(ISBLANK($G$2),SUMIFS(Saidas!C:C,Saidas!A:A,'Cadastro-Estoque'!A:A),SUMIFS(Saidas!C:C,Saidas!A:A,'Cadastro-Estoque'!A:A,Saidas!B:B,CONCATENATE("<=",$G$2)))=0,1,IF(ISBLANK($G$2),SUMIFS(Saidas!C:C,Saidas!A:A,'Cadastro-Estoque'!A:A),SUMIFS(Saidas!C:C,Saidas!A:A,'Cadastro-Estoque'!A:A,Saidas!B:B,CONCATENATE("<=",$G$2)))) -> 0 | K6: =#REF! -> #REF!
A7: 016-30X400 | B7: FLOCADO VITABRAS 30 X 400 | C7: FARDOS | D7: ADRAM | F7: 341 | G7: =IF(ISBLANK($G$2),SUMIFS(Entradas!C:C,Entradas!A:A,'Cadastro-Estoque'!A:A)-SUMIFS(Saidas!C:C,Saidas!A:A,'Cadastro-Estoque'!A:A),SUMIFS(Entradas!C:C,Entradas!A:A,'Cadastro-Estoque'!A:A,Entradas!B:B,CONCATENATE("<=",$G$2))-SUMIFS(Saidas!C:C,Saidas!A:A,'Cadastro-Estoque'!A:A,Saidas!B:B,CONCATENATE("<=",$G$2)))+F7 -> 341 | H7: 21 | I7: =IF(ISBLANK($G$2),SUMIFS(Saidas!E:E,Saidas!A:A,'Cadastro-Estoque'!A:A),SUMIFS(Saidas!E:E,Saidas!A:A,'Cadastro-Estoque'!A:A,Saidas!B:B,CONCATENATE("<=",$G$2)))/IF(IF(ISBLANK($G$2),SUMIFS(Saidas!C:C,Saidas!A:A,'Cadastro-Estoque'!A:A),SUMIFS(Saidas!C:C,Saidas!A:A,'Cadastro-Estoque'!A:A,Saidas!B:B,CONCATENATE("<=",$G$2)))=0,1,IF(ISBLANK($G$2),SUMIFS(Saidas!C:C,Saidas!A:A,'Cadastro-Estoque'!A:A),SUMIFS(Saidas!C:C,Saidas!A:A,'Cadastro-Estoque'!A:A,Saidas!B:B,CONCATENATE("<=",$G$2)))) -> 0 | K7: =#REF! -> #REF!
A8: 022-30X500 | B8: FLOCADO VITABRASIL 30 X 500 | C8: FARDOS | D8: ADRAM | F8: 0 | G8: =IF(ISBLANK($G$2),SUMIFS(Entradas!C:C,Entradas!A:A,'Cadastro-Estoque'!A:A)-SUMIFS(Saidas!C:C,Saidas!A:A,'Cadastro-Estoque'!A:A),SUMIFS(Entradas!C:C,Entradas!A:A,'Cadastro-Estoque'!A:A,Entradas!B:B,CONCATENATE("<=",$G$2))-SUMIFS(Saidas!C:C,Saidas!A:A,'Cadastro-Estoque'!A:A,Saidas!B:B,CONCATENATE("<=",$G$2)))+F8 -> 0 | H8: =IF(ISBLANK($G$2),SUMIFS(Entradas!E:E,Entradas!A:A,'Cadastro-Estoque'!A:A),SUMIFS(Entradas!E:E,Entradas!A:A,'Cadastro-Estoque'!A:A,Entradas!B:B,CONCATENATE("<=",$G$2)))/IF(IF(ISBLANK($G$2),SUMIFS(Entradas!C:C,Entradas!A:A,'Cadastro-Estoque'!A:A),SUMIFS(Entradas!C:C,Entradas!A:A,'Cadastro-Estoque'!A:A,Entradas!B:B,CONCATENATE("<=",$G$2)))=0,1,IF(ISBLANK($G$2),SUMIFS(Entradas!C:C,Entradas!A:A,'Cadastro-Estoque'!A:A),SUMIFS(Entradas!C:C,Entradas!A:A,'Cadastro-Estoque'!A:A,Entradas!B:B,CONCATENATE("<=",$G$2)))) -> 0 | I8: =IF(ISBLANK($G$2),SUMIFS(Saidas!E:E,Saidas!A:A,'Cadastro-Estoque'!A:A),SUMIFS(Saidas!E:E,Saidas!A:A,'Cadastro-Estoque'!A:A,Saidas!B:B,CONCATENATE("<=",$G$2)))/IF(IF(ISBLANK($G$2),SUMIFS(Saidas!C:C,Saidas!A:A,'Cadastro-Estoque'!A:A),SUMIFS(Saidas!C:C,Saidas!A:A,'Cadastro-Estoque'!A:A,Saidas!B:B,CONCATENATE("<=",$G$2)))=0,1,IF(ISBLANK($G$2),SUMIFS(Saidas!C:C,Saidas!A:A,'Cadastro-Estoque'!A:A),SUMIFS(Saidas!C:C,Saidas!A:A,'Cadastro-Estoque'!A:A,Saidas!B:B,CONCATENATE("<=",$G$2)))) -> 0 | K8: =#REF! -> #REF!
A9: 019-12X500 | B9: FLOCADO PURO MILHO 12 X 500 | C9: FARDOS | D9: ADRAM | F9: 0 | G9: =IF(ISBLANK($G$2),SUMIFS(Entradas!C:C,Entradas!A:A,'Cadastro-Estoque'!A:A)-SUMIFS(Saidas!C:C,Saidas!A:A,'Cadastro-Estoque'!A:A),SUMIFS(Entradas!C:C,Entradas!A:A,'Cadastro-Estoque'!A:A,Entradas!B:B,CONCATENATE("<=",$G$2))-SUMIFS(Saidas!C:C,Saidas!A:A,'Cadastro-Estoque'!A:A,Saidas!B:B,CONCATENATE("<=",$G$2)))+F9 -> 0 | H9: =IF(ISBLANK($G$2),SUMIFS(Entradas!E:E,Entradas!A:A,'Cadastro-Estoque'!A:A),SUMIFS(Entradas!E:E,Entradas!A:A,'Cadastro-Estoque'!A:A,Entradas!B:B,CONCATENATE("<=",$G$2)))/IF(IF(ISBLANK($G$2),SUMIFS(Entradas!C:C,Entradas!A:A,'Cadastro-Estoque'!A:A),SUMIFS(Entradas!C:C,Entradas!A:A,'Cadastro-Estoque'!A:A,Entradas!B:B,CONCATENATE("<=",$G$2)))=0,1,IF(ISBLANK($G$2),SUMIFS(Entradas!C:C,Entradas!A:A,'Cadastro-Estoque'!A:A),SUMIFS(Entradas!C:C,Entradas!A:A,'Cadastro-Estoque'!A:A,Entradas!B:B,CONCATENATE("<=",$G$2)))) -> 0 | I9: =IF(ISBLANK($G$2),SUMIFS(Saidas!E:E,Saidas!A:A,'Cadastro-Estoque'!A:A),SUMIFS(Saidas!E:E,Saidas!A:A,'Cadastro-Estoque'!A:A,Saidas!B:B,CONCATENATE("<=",$G$2)))/IF(IF(ISBLANK($G$2),SUMIFS(Saidas!C:C,Saidas!A:A,'Cadastro-Estoque'!A:A),SUMIFS(Saidas!C:C,Saidas!A:A,'Cadastro-Estoque'!A:A,Saidas!B:B,CONCATENATE("<=",$G$2)))=0,1,IF(ISBLANK($G$2),SUMIFS(Saidas!C:C,Saidas!A:A,'Cadastro-Estoque'!A:A),SUMIFS(Saidas!C:C,Saidas!A:A,'Cadastro-Estoque'!A:A,Saidas!B:B,CONCATENATE("<=",$G$2)))) -> 0 | K9: =#REF! -> #REF!
A10: 019-30X500 | B10: FLOCADO PURO MILHO 30 X 500 | C10: FARDOS | D10: ADRAM | F10: 2081 | G10: =IF(ISBLANK($G$2),SUMIFS(Entradas!C:C,Entradas!A:A,'Cadastro-Estoque'!A:A)-SUMIFS(Saidas!C:C,Saidas!A:A,'Cadastro-Estoque'!A:A),SUMIFS(Entradas!C:C,Entradas!A:A,'Cadastro-Estoque'!A:A,Entradas!B:B,CONCATENATE("<=",$G$2))-SUMIFS(Saidas!C:C,Saidas!A:A,'Cadastro-Estoque'!A:A,Saidas!B:B,CONCATENATE("<=",$G$2)))+F10 -> 2081 | H10: =IF(ISBLANK($G$2),SUMIFS(Entradas!E:E,Entradas!A:A,'Cadastro-Estoque'!A:A),SUMIFS(Entradas!E:E,Entradas!A:A,'Cadastro-Estoque'!A:A,Entradas!B:B,CONCATENATE("<=",$G$2)))/IF(IF(ISBLANK($G$2),SUMIFS(Entradas!C:C,Entradas!A:A,'Cadastro-Estoque'!A:A),SUMIFS(Entradas!C:C,Entradas!A:A,'Cadastro-Estoque'!A:A,Entradas!B:B,CONCATENATE("<=",$G$2)))=0,1,IF(ISBLANK($G$2),SUMIFS(Entradas!C:C,Entradas!A:A,'Cadastro-Estoque'!A:A),SUMIFS(Entradas!C:C,Entradas!A:A,'Cadastro-Estoque'!A:A,Entradas!B:B,CONCATENATE("<=",$G$2)))) -> 0 | I10: =IF(ISBLANK($G$2),SUMIFS(Saidas!E:E,Saidas!A:A,'Cadastro-Estoque'!A:A),SUMIFS(Saidas!E:E,Saidas!A:A,'Cadastro-Estoque'!A:A,Saidas!B:B,CONCATENATE("<=",$G$2)))/IF(IF(ISBLANK($G$2),SUMIFS(Saidas!C:C,Saidas!A:A,'Cadastro-Estoque'!A:A),SUMIFS(Saidas!C:C,Saidas!A:A,'Cadastro-Estoque'!A:A,Saidas!B:B,CONCATENATE("<=",$G$2)))=0,1,IF(ISBLANK($G$2),SUMIFS(Saidas!C:C,Saidas!A:A,'Cadastro-Estoque'!A:A),SUMIFS(Saidas!C:C,Saidas!A:A,'Cadastro-Estoque'!A:A,Saidas!B:B,CONCATENATE("<=",$G$2)))) -> 0 | K10: =#REF! -> #REF!
A11: 050-30X500 | B11: FLOCADO CORDEIRO 30 X 500 | C11: FARDOS | D11: ADRAM | F11: 0 | G11: =IF(ISBLANK($G$2),SUMIFS(Entradas!C:C,Entradas!A:A,'Cadastro-Estoque'!A:A)-SUMIFS(Saidas!C:C,Saidas!A:A,'Cadastro-Estoque'!A:A),SUMIFS(Entradas!C:C,Entradas!A:A,'Cadastro-Estoque'!A:A,Entradas!B:B,CONCATENATE("<=",$G$2))-SUMIFS(Saidas!C:C,Saidas!A:A,'Cadastro-Estoque'!A:A,Saidas!B:B,CONCATENATE("<=",$G$2)))+F11 -> 0 | H11: =IF(ISBLANK($G$2),SUMIFS(Entradas!E:E,Entradas!A:A,'Cadastro-Estoque'!A:A),SUMIFS(Entradas!E:E,Entradas!A:A,'Cadastro-Estoque'!A:A,Entradas!B:B,CONCATENATE("<=",$G$2)))/IF(IF(ISBLANK($G$2),SUMIFS(Entradas!C:C,Entradas!A:A,'Cadastro-Estoque'!A:A),SUMIFS(Entradas!C:C,Entradas!A:A,'Cadastro-Estoque'!A:A,Entradas!B:B,CONCATENATE("<=",$G$2)))=0,1,IF(ISBLANK($G$2),SUMIFS(Entradas!C:C,Entradas!A:A,'Cadastro-Estoque'!A:A),SUMIFS(Entradas!C:C,Entradas!A:A,'Cadastro-Estoque'!A:A,Entradas!B:B,CONCATENATE("<=",$G$2)))) -> 0 | I11: =IF(ISBLANK($G$2),SUMIFS(Saidas!E:E,Saidas!A:A,'Cadastro-Estoque'!A:A),SUMIFS(Saidas!E:E,Saidas!A:A,'Cadastro-Estoque'!A:A,Saidas!B:B,CONCATENATE("<=",$G$2)))/IF(IF(ISBLANK($G$2),SUMIFS(Saidas!C:C,Saidas!A:A,'Cadastro-Estoque'!A:A),SUMIFS(Saidas!C:C,Saidas!A:A,'Cadastro-Estoque'!A:A,Saidas!B:B,CONCATENATE("<=",$G$2)))=0,1,IF(ISBLANK($G$2),SUMIFS(Saidas!C:C,Saidas!A:A,'Cadastro-Estoque'!A:A),SUMIFS(Saidas!C:C,Saidas!A:A,'Cadastro-Estoque'!A:A,Saidas!B:B,CONCATENATE("<=",$G$2)))) -> 0 | K11: =#REF! -> #REF!
A12: 094-12X500 | B12: FLOCADO M & K 12 X 500 | C12: FARDOS | D12: ADRAM | F12: 0 | G12: =IF(ISBLANK($G$2),SUMIFS(Entradas!C:C,Entradas!A:A,'Cadastro-Estoque'!A:A)-SUMIFS(Saidas!C:C,Saidas!A:A,'Cadastro-Estoque'!A:A),SUMIFS(Entradas!C:C,Entradas!A:A,'Cadastro-Estoque'!A:A,Entradas!B:B,CONCATENATE("<=",$G$2))-SUMIFS(Saidas!C:C,Saidas!A:A,'Cadastro-Estoque'!A:A,Saidas!B:B,CONCATENATE("<=",$G$2)))+F12 -> 0 | H12: =IF(ISBLANK($G$2),SUMIFS(Entradas!E:E,Entradas!A:A,'Cadastro-Estoque'!A:A),SUMIFS(Entradas!E:E,Entradas!A:A,'Cadastro-Estoque'!A:A,Entradas!B:B,CONCATENATE("<=",$G$2)))/IF(IF(ISBLANK($G$2),SUMIFS(Entradas!C:C,Entradas!A:A,'Cadastro-Estoque'!A:A),SUMIFS(Entradas!C:C,Entradas!A:A,'Cadastro-Estoque'!A:A,Entradas!B:B,CONCATENATE("<=",$G$2)))=0,1,IF(ISBLANK($G$2),SUMIFS(Entradas!C:C,Entradas!A:A,'Cadastro-Estoque'!A:A),SUMIFS(Entradas!C:C,Entradas!A:A,'Cadastro-Estoque'!A:A,Entradas!B:B,CONCATENATE("<=",$G$2)))) -> 0 | I12: =IF(ISBLANK($G$2),SUMIFS(Saidas!E:E,Saidas!A:A,'Cadastro-Estoque'!A:A),SUMIFS(Saidas!E:E,Saidas!A:A,'Cadastro-Estoque'!A:A,Saidas!B:B,CONCATENATE("<=",$G$2)))/IF(IF(ISBLANK($G$2),SUMIFS(Saidas!C:C,Saidas!A:A,'Cadastro-Estoque'!A:A),SUMIFS(Saidas!C:C,Saidas!A:A,'Cadastro-Estoque'!A:A,Saidas!B:B,CONCATENATE("<=",$G$2)))=0,1,IF(ISBLANK($G$2),SUMIFS(Saidas!C:C,Saidas!A:A,'Cadastro-Estoque'!A:A),SUMIFS(Saidas!C:C,Saidas!A:A,'Cadastro-Estoque'!A:A,Saidas!B:B,CONCATENATE("<=",$G$2)))) -> 0 | K12: =#REF! -> #REF!
F13: 0 | G13: =IF(ISBLANK($G$2),SUMIFS(Entradas!C:C,Entradas!A:A,'Cadastro-Estoque'!A:A)-SUMIFS(Saidas!C:C,Saidas!A:A,'Cadastro-Estoque'!A:A),SUMIFS(Entradas!C:C,Entradas!A:A,'Cadastro-Estoque'!A:A,Entradas!B:B,CONCATENATE("<=",$G$2))-SUMIFS(Saidas!C:C,Saidas!A:A,'Cadastro-Estoque'!A:A,Saidas!B:B,CONCATENATE("<=",$G$2)))+F13 -> 0 | H13: =IF(ISBLANK($G$2),SUMIFS(Entradas!E:E,Entradas!A:A,'Cadastro-Estoque'!A:A),SUMIFS(Entradas!E:E,Entradas!A:A,'Cadastro-Estoque'!A:A,Entradas!B:B,CONCATENATE("<=",$G$2)))/IF(IF(ISBLANK($G$2),SUMIFS(Entradas!C:C,Entradas!A:A,'Cadastro-Estoque'!A:A),SUMIFS(Entradas!C:C,Entradas!A:A,'Cadastro-Estoque'!A:A,Entradas!B:B,CONCATENATE("<=",$G$2)))=0,1,IF(ISBLANK($G$2),SUMIFS(Entradas!C:C,Entradas!A:A,'Cadastro-Estoque'!A:A),SUMIFS(Entradas!C:C,Entradas!A:A,'Cadastro-Estoque'!A:A,Entradas!B:B,CONCATENATE("<=",$G$2)))) -> 0 | I13: =IF(ISBLANK($G$2),SUMIFS(Saidas!E:E,Saidas!A:A,'Cadastro-Estoque'!A:A),SUMIFS(Saidas!E:E,Saidas!A:A,'Cadastro-Estoque'!A:A,Saidas!B:B,CONCATENATE("<=",$G$2)))/IF(IF(ISBLANK($G$2),SUMIFS(Saidas!C:C,Saidas!A:A,'Cadastro-Estoque'!A:A),SUMIFS(Saidas!C:C,Saidas!A:A,'Cadastro-Estoque'!A:A,Saidas!B:B,CONCATENATE("<=",$G$2)))=0,1,IF(ISBLANK($G$2),SUMIFS(Saidas!C:C,Saidas!A:A,'Cadastro-Estoque'!A:A),SUMIFS(Saidas!C:C,Saidas!A:A,'Cadastro-Estoque'!A:A,Saidas!B:B,CONCATENATE("<=",$G$2)))) -> 0 | K13: 0
A14: 036-12X500 | B14: POLENTA KISABOR 12 X 500 | C14: FARDOS | D14: ADRAM | F14: 0 | G14: =IF(ISBLANK($G$2),SUMIFS(Entradas!C:C,Entradas!A:A,'Cadastro-Estoque'!A:A)-SUMIFS(Saidas!C:C,Saidas!A:A,'Cadastro-Estoque'!A:A),SUMIFS(Entradas!C:C,Entradas!A:A,'Cadastro-Estoque'!A:A,Entradas!B:B,CONCATENATE("<=",$G$2))-SUMIFS(Saidas!C:C,Saidas!A:A,'Cadastro-Estoque'!A:A,Saidas!B:B,CONCATENATE("<=",$G$2)))+F14 -> 0 | H14: =IF(ISBLANK($G$2),SUMIFS(Entradas!E:E,Entradas!A:A,'Cadastro-Estoque'!A:A),SUMIFS(Entradas!E:E,Entradas!A:A,'Cadastro-Estoque'!A:A,Entradas!B:B,CONCATENATE("<=",$G$2)))/IF(IF(ISBLANK($G$2),SUMIFS(Entradas!C:C,Entradas!A:A,'Cadastro-Estoque'!A:A),SUMIFS(Entradas!C:C,Entradas!A:A,'Cadastro-Estoque'!A:A,Entradas!B:B,CONCATENATE("<=",$G$2)))=0,1,IF(ISBLANK($G$2),SUMIFS(Entradas!C:C,Entradas!A:A,'Cadastro-Estoque'!A:A),SUMIFS(Entradas!C:C,Entradas!A:A,'Cadastro-Estoque'!A:A,Entradas!B:B,CONCATENATE("<=",$G$2)))) -> 0 | I14: =IF(ISBLANK($G$2),SUMIFS(Saidas!E:E,Saidas!A:A,'Cadastro-Estoque'!A:A),SUMIFS(Saidas!E:E,Saidas!A:A,'Cadastro-Estoque'!A:A,Saidas!B:B,CONCATENATE("<=",$G$2)))/IF(IF(ISBLANK($G$2),SUMIFS(Saidas!C:C,Saidas!A:A,'Cadastro-Estoque'!A:A),SUMIFS(Saidas!C:C,Saidas!A:A,'Cadastro-Estoque'!A:A,Saidas!B:B,CONCATENATE("<=",$G$2)))=0,1,IF(ISBLANK($G$2),SUMIFS(Saidas!C:C,Saidas!A:A,'Cadastro-Estoque'!A:A),SUMIFS(Saidas!C:C,Saidas!A:A,'Cadastro-Estoque'!A:A,Saidas!B:B,CONCATENATE("<=",$G$2)))) -> 0 | K14: =#REF! -> #REF!
A15: 036-30X500 | B15: POLENTA KISABOR 30 X 500 | C15: FARDOS | D15: ADRAM | F15: 0 | G15: =IF(ISBLANK($G$2),SUMIFS(Entradas!C:C,Entradas!A:A,'Cadastro-Estoque'!A:A)-SUMIFS(Saidas!C:C,Saidas!A:A,'Cadastro-Estoque'!A:A),SUMIFS(Entradas!C:C,Entradas!A:A,'Cadastro-Estoque'!A:A,Entradas!B:B,CONCATENATE("<=",$G$2))-SUMIFS(Saidas!C:C,Saidas!A:A,'Cadastro-Estoque'!A:A,Saidas!B:B,CONCATENATE("<=",$G$2)))+F15 -> 0 | H15: =IF(ISBLANK($G$2),SUMIFS(Entradas!E:E,Entradas!A:A,'Cadastro-Estoque'!A:A),SUMIFS(Entradas!E:E,Entradas!A:A,'Cadastro-Estoque'!A:A,Entradas!B:B,CONCATENATE("<=",$G$2)))/IF(IF(ISBLANK($G$2),SUMIFS(Entradas!C:C,Entradas!A:A,'Cadastro-Estoque'!A:A),SUMIFS(Entradas!C:C,Entradas!A:A,'Cadastro-Estoque'!A:A,Entradas!B:B,CONCATENATE("<=",$G$2)))=0,1,IF(ISBLANK($G$2),SUMIFS(Entradas!C:C,Entradas!A:A,'Cadastro-Estoque'!A:A),SUMIFS(Entradas!C:C,Entradas!A:A,'Cadastro-Estoque'!A:A,Entradas!B:B,CONCATENATE("<=",$G$2)))) -> 0 | I15: =IF(ISBLANK($G$2),SUMIFS(Saidas!E:E,Saidas!A:A,'Cadastro-Estoque'!A:A),SUMIFS(Saidas!E:E,Saidas!A:A,'Cadastro-Estoque'!A:A,Saidas!B:B,CONCATENATE("<=",$G$2)))/IF(IF(ISBLANK($G$2),SUMIFS(Saidas!C:C,Saidas!A:A,'Cadastro-Estoque'!A:A),SUMIFS(Saidas!C:C,Saidas!A:A,'Cadastro-Estoque'!A:A,Saidas!B:B,CONCATENATE("<=",$G$2)))=0,1,IF(ISBLANK($G$2),SUMIFS(Saidas!C:C,Saidas!A:A,'Cadastro-Estoque'!A:A),SUMIFS(Saidas!C:C,Saidas!A:A,'Cadastro-Estoque'!A:A,Saidas!B:B,CONCATENATE("<=",$G$2)))) -> 0 | K15: =#REF! -> #REF!
A16: 037-30X500 | B16: POLENTA NUTRIVITA 30 X 500 | C16: FARDOS | D16: ADRAM | F16: 239 | G16: =IF(ISBLANK($G$2),SUMIFS(Entradas!C:C,Entradas!A:A,'Cadastro-Estoque'!A:A)-SUMIFS(Saidas!C:C,Saidas!A:A,'Cadastro-Estoque'!A:A),SUMIFS(Entradas!C:C,Entradas!A:A,'Cadastro-Estoque'!A:A,Entradas!B:B,CONCATENATE("<=",$G$2))-SUMIFS(Saidas!C:C,Saidas!A:A,'Cadastro-Estoque'!A:A,Saidas!B:B,CONCATENATE("<=",$G$2)))+F16 -> 239 | H16: =IF(ISBLANK($G$2),SUMIFS(Entradas!E:E,Entradas!A:A,'Cadastro-Estoque'!A:A),SUMIFS(Entradas!E:E,Entradas!A:A,'Cadastro-Estoque'!A:A,Entradas!B:B,CONCATENATE("<=",$G$2)))/IF(IF(ISBLANK($G$2),SUMIFS(Entradas!C:C,Entradas!A:A,'Cadastro-Estoque'!A:A),SUMIFS(Entradas!C:C,Entradas!A:A,'Cadastro-Estoque'!A:A,Entradas!B:B,CONCATENATE("<=",$G$2)))=0,1,IF(ISBLANK($G$2),SUMIFS(Entradas!C:C,Entradas!A:A,'Cadastro-Estoque'!A:A),SUMIFS(Entradas!C:C,Entradas!A:A,'Cadastro-Estoque'!A:A,Entradas!B:B,CONCATENATE("<=",$G$2)))) -> 0 | I16: =IF(ISBLANK($G$2),SUMIFS(Saidas!E:E,Saidas!A:A,'Cadastro-Estoque'!A:A),SUMIFS(Saidas!E:E,Saidas!A:A,'Cadastro-Estoque'!A:A,Saidas!B:B,CONCATENATE("<=",$G$2)))/IF(IF(ISBLANK($G$2),SUMIFS(Saidas!C:C,Saidas!A:A,'Cadastro-Estoque'!A:A),SUMIFS(Saidas!C:C,Saidas!A:A,'Cadastro-Estoque'!A:A,Saidas!B:B,CONCATENATE("<=",$G$2)))=0,1,IF(ISBLANK($G$2),SUMIFS(Saidas!C:C,Saidas!A:A,'Cadastro-Estoque'!A:A),SUMIFS(Saidas!C:C,Saidas!A:A,'Cadastro-Estoque'!A:A,Saidas!B:B,CONCATENATE("<=",$G$2)))) -> 0 | K16: =#REF! -> #REF!
A17: 037-30X400 | B17: POLENTA NUTRIVITA 30 X 400 | C17: FARDOS | D17: ADRAM | F17: 2100 | G17: =IF(ISBLANK($G$2),SUMIFS(Entradas!C:C,Entradas!A:A,'Cadastro-Estoque'!A:A)-SUMIFS(Saidas!C:C,Saidas!A:A,'Cadastro-Estoque'!A:A),SUMIFS(Entradas!C:C,Entradas!A:A,'Cadastro-Estoque'!A:A,Entradas!B:B,CONCATENATE("<=",$G$2))-SUMIFS(Saidas!C:C,Saidas!A:A,'Cadastro-Estoque'!A:A,Saidas!B:B,CONCATENATE("<=",$G$2)))+F17 -> 2100 | I17: =IF(ISBLANK($G$2),SUMIFS(Saidas!E:E,Saidas!A:A,'Cadastro-Estoque'!A:A),SUMIFS(Saidas!E:E,Saidas!A:A,'Cadastro-Estoque'!A:A,Saidas!B:B,CONCATENATE("<=",$G$2)))/IF(IF(ISBLANK($G$2),SUMIFS(Saidas!C:C,Saidas!A:A,'Cadastro-Estoque'!A:A),SUMIFS(Saidas!C:C,Saidas!A:A,'Cadastro-Estoque'!A:A,Saidas!B:B,CONCATENATE("<=",$G$2)))=0,1,IF(ISBLANK($G$2),SUMIFS(Saidas!C:C,Saidas!A:A,'Cadastro-Estoque'!A:A),SUMIFS(Saidas!C:C,Saidas!A:A,'Cadastro-Estoque'!A:A,Saidas!B:B,CONCATENATE("<=",$G$2)))) -> 0
A18: 039-12X500 | B18: POLENTA CBS 12 X 500 | C18: FARDOS | D18: ADRAM | F18: 74 | G18: =IF(ISBLANK($G$2),SUMIFS(Entradas!C:C,Entradas!A:A,'Cadastro-Estoque'!A:A)-SUMIFS(Saidas!C:C,Saidas!A:A,'Cadastro-Estoque'!A:A),SUMIFS(Entradas!C:C,Entradas!A:A,'Cadastro-Estoque'!A:A,Entradas!B:B,CONCATENATE("<=",$G$2))-SUMIFS(Saidas!C:C,Saidas!A:A,'Cadastro-Estoque'!A:A,Saidas!B:B,CONCATENATE("<=",$G$2)))+F18 -> 74 | H18: =IF(ISBLANK($G$2),SUMIFS(Entradas!E:E,Entradas!A:A,'Cadastro-Estoque'!A:A),SUMIFS(Entradas!E:E,Entradas!A:A,'Cadastro-Estoque'!A:A,Entradas!B:B,CONCATENATE("<=",$G$2)))/IF(IF(ISBLANK($G$2),SUMIFS(Entradas!C:C,Entradas!A:A,'Cadastro-Estoque'!A:A),SUMIFS(Entradas!C:C,Entradas!A:A,'Cadastro-Estoque'!A:A,Entradas!B:B,CONCATENATE("<=",$G$2)))=0,1,IF(ISBLANK($G$2),SUMIFS(Entradas!C:C,Entradas!A:A,'Cadastro-Estoque'!A:A),SUMIFS(Entradas!C:C,Entradas!A:A,'Cadastro-Estoque'!A:A,Entradas!B:B,CONCATENATE("<=",$G$2)))) -> 0 | I18: =IF(ISBLANK($G$2),SUMIFS(Saidas!E:E,Saidas!A:A,'Cadastro-Estoque'!A:A),SUMIFS(Saidas!E:E,Saidas!A:A,'Cadastro-Estoque'!A:A,Saidas!B:B,CONCATENATE("<=",$G$2)))/IF(IF(ISBLANK($G$2),SUMIFS(Saidas!C:C,Saidas!A:A,'Cadastro-Estoque'!A:A),SUMIFS(Saidas!C:C,Saidas!A:A,'Cadastro-Estoque'!A:A,Saidas!B:B,CONCATENATE("<=",$G$2)))=0,1,IF(ISBLANK($G$2),SUMIFS(Saidas!C:C,Saidas!A:A,'Cadastro-Estoque'!A:A),SUMIFS(Saidas!C:C,Saidas!A:A,'Cadastro-Estoque'!A:A,Saidas!B:B,CONCATENATE("<=",$G$2)))) -> 0 | K18: =#REF! -> #REF!
A19: 052-12X500 | B19: POLENTA FRITZ E FRIDA 12 X 500 | C19: FARDOS | D19: ADRAM | F19: 0 | G19: =IF(ISBLANK($G$2),SUMIFS(Entradas!C:C,Entradas!A:A,'Cadastro-Estoque'!A:A)-SUMIFS(Saidas!C:C,Saidas!A:A,'Cadastro-Estoque'!A:A),SUMIFS(Entradas!C:C,Entradas!A:A,'Cadastro-Estoque'!A:A,Entradas!B:B,CONCATENATE("<=",$G$2))-SUMIFS(Saidas!C:C,Saidas!A:A,'Cadastro-Estoque'!A:A,Saidas!B:B,CONCATENATE("<=",$G$2)))+F19 -> 0 | H19: =IF(ISBLANK($G$2),SUMIFS(Entradas!E:E,Entradas!A:A,'Cadastro-Estoque'!A:A),SUMIFS(Entradas!E:E,Entradas!A:A,'Cadastro-Estoque'!A:A,Entradas!B:B,CONCATENATE("<=",$G$2)))/IF(IF(ISBLANK($G$2),SUMIFS(Entradas!C:C,Entradas!A:A,'Cadastro-Estoque'!A:A),SUMIFS(Entradas!C:C,Entradas!A:A,'Cadastro-Estoque'!A:A,Entradas!B:B,CONCATENATE("<=",$G$2)))=0,1,IF(ISBLANK($G$2),SUMIFS(Entradas!C:C,Entradas!A:A,'Cadastro-Estoque'!A:A),SUMIFS(Entradas!C:C,Entradas!A:A,'Cadastro-Estoque'!A:A,Entradas!B:B,CONCATENATE("<=",$G$2)))) -> 0 | I19: =IF(ISBLANK($G$2),SUMIFS(Saidas!E:E,Saidas!A:A,'Cadastro-Estoque'!A:A),SUMIFS(Saidas!E:E,Saidas!A:A,'Cadastro-Estoque'!A:A,Saidas!B:B,CONCATENATE("<=",$G$2)))/IF(IF(ISBLANK($G$2),SUMIFS(Saidas!C:C,Saidas!A:A,'Cadastro-Estoque'!A:A),SUMIFS(Saidas!C:C,Saidas!A:A,'Cadastro-Estoque'!A:A,Saidas!B:B,CONCATENATE("<=",$G$2)))=0,1,IF(ISBLANK($G$2),SUMIFS(Saidas!C:C,Saidas!A:A,'Cadastro-Estoque'!A:A),SUMIFS(Saidas!C:C,Saidas!A:A,'Cadastro-Estoque'!A:A,Saidas!B:B,CONCATENATE("<=",$G$2)))) -> 0 | K19: =#REF! -> #REF!
A20: 064-12X1 | B20: POLENTA PERDIZ 12 X 1K | C20: FARDOS | D20: ADRAM | F20: 0 | G20: =IF(ISBLANK($G$2),SUMIFS(Entradas!C:C,Entradas!A:A,'Cadastro-Estoque'!A:A)-SUMIFS(Saidas!C:C,Saidas!A:A,'Cadastro-Estoque'!A:A),SUMIFS(Entradas!C:C,Entradas!A:A,'Cadastro-Estoque'!A:A,Entradas!B:B,CONCATENATE("<=",$G$2))-SUMIFS(Saidas!C:C,Saidas!A:A,'Cadastro-Estoque'!A:A,Saidas!B:B,CONCATENATE("<=",$G$2)))+F20 -> 0 | H20: =IF(ISBLANK($G$2),SUMIFS(Entradas!E:E,Entradas!A:A,'Cadastro-Estoque'!A:A),SUMIFS(Entradas!E:E,Entradas!A:A,'Cadastro-Estoque'!A:A,Entradas!B:B,CONCATENATE("<=",$G$2)))/IF(IF(ISBLANK($G$2),SUMIFS(Entradas!C:C,Entradas!A:A,'Cadastro-Estoque'!A:A),SUMIFS(Entradas!C:C,Entradas!A:A,'Cadastro-Estoque'!A:A,Entradas!B:B,CONCATENATE("<=",$G$2)))=0,1,IF(ISBLANK($G$2),SUMIFS(Entradas!C:C,Entradas!A:A,'Cadastro-Estoque'!A:A),SUMIFS(Entradas!C:C,Entradas!A:A,'Cadastro-Estoque'!A:A,Entradas!B:B,CONCATENATE("<=",$G$2)))) -> 0 | I20: =IF(ISBLANK($G$2),SUMIFS(Saidas!E:E,Saidas!A:A,'Cadastro-Estoque'!A:A),SUMIFS(Saidas!E:E,Saidas!A:A,'Cadastro-Estoque'!A:A,Saidas!B:B,CONCATENATE("<=",$G$2)))/IF(IF(ISBLANK($G$2),SUMIFS(Saidas!C:C,Saidas!A:A,'Cadastro-Estoque'!A:A),SUMIFS(Saidas!C:C,Saidas!A:A,'Cadastro-Estoque'!A:A,Saidas!B:B,CONCATENATE("<=",$G$2)))=0,1,IF(ISBLANK($G$2),SUMIFS(Saidas!C:C,Saidas!A:A,'Cadastro-Estoque'!A:A),SUMIFS(Saidas!C:C,Saidas!A:A,'Cadastro-Estoque'!A:A,Saidas!B:B,CONCATENATE("<=",$G$2)))) -> 0 | K20: =#REF! -> #REF!
